Workbook

Sheet Employee Details_GnDataset
A1: DATASET TAKEN :EMPLOYEE DETAILS
A2: Employee ID | B2: Name | C2: Department | D2: Country | E2: Salary | F2: Date of Joining | G2: Performance Rating | H2: Gender | I2: Email
A3: EMP1000 | C3: Finance | E3: N/A | G3: 2 | H3: Unknown | I3: invalid_email
A4: EMP1001 | B4: Eve Adams | C4: HR | D4: Germany | E4: 54255 | F4: 42015 | G4: 1 | H4: Other | I4: user106@example.com
A5: EMP1002 | B5: Alice Brown | C5: Finance | D5: Germany | E5: 63184 | F5: 42022 | G5: 2 | I5: user176@example.com
A6: EMP1003 | B6: John Doe | C6: Sales | D6: USA | E6: 94406 | F6: 42029 | G6: 1 | H6: Male | I6: user168@example.com
A7: EMP1004 | B7: Jane Smith | C7: Sales | D7: Germany | E7: 64120 | F7: 42036 | G7: 1 | H7: Male | I7: user49@example.com
A8: EMP1005 | B8: Alice Brown | C8: IT | D8: India | E8: 78421 | F8: 42043 | G8: 2 | H8: Female | I8: user24@example.com
A9: EMP1006 | B9: Sam Wilson | C9: Sales | E9: 67721 | F9: 42050 | H9: Male | I9: user168@example.com
A10: EMP1007 | B10: Chris Lee | C10: Marketing | E10: 35364 | F10: 42057 | G10: 2 | H10: Other | I10: user26@example.com
A11: EMP1008 | B11: Alice Brown | C11: IT | D11: Germany | E11: 97881 | F11: 42064 | H11: Female | I11: user25@example.com
A12: EMP1009 | B12: Chris Lee | C12: HR | D12: UK | E12: 91846 | F12: 42071 | H12: Male | I12: user153@example.com
A13: EMP1010 | B13: Sam Wilson | C13: Finance | D13: UK | E13: 64247 | F13: 42078 | G13: 1 | H13: Female | I13: user18@example.com
A14: EMP1011 | B14: Sam Wilson | C14: IT | D14: USA | E14: 91180 | F14: 42085 | G14: 5 | H14: Male | I14: user1@example.com
A15: EMP1012 | B15: Bob Johnson | C15: Sales | E15: 96418 | F15: 42092 | G15: 5 | H15: Male | I15: user106@example.com
A16: EMP1013 | B16: Sam Wilson | D16: India | E16: 62158 | F16: 42099 | G16: 4 | I16: user180@example.com
A17: EMP1014 | B17: Jane Smith | C17: HR | E17: 59894 | F17: 42106 | G17: 2 | H17: Male | I17: user184@example.com
A18: EMP1015 | C18: IT | D18: India | E18: 92443 | F18: 42113 | G18: 3 | H18: Other | I18: user3@example.com
A19: EMP1016 | B19: Bob Johnson | D19: Germany | E19: 90271 | F19: 42120 | I19: user64@example.com
A20: EMP1017 | B20: Jane Smith | C20: Finance | D20: Australia | E20: 41341 | F20: 42127 | G20: 1 | H20: Other | I20: user38@example.com
A21: EMP1018 | B21: Alice Brown | C21: Finance | D21: UK | E21: 73602 | F21: 42134 | I21: user96@example.com
A22: EMP1019 | B22: Eve Adams | D22: India | E22: 67531 | F22: 42141 | G22: 5 | H22: Female | I22: user151@example.com
A23: EMP1020 | B23: Jane Smith | C23: HR | D23: USA | E23: N/A | F23: 42148 | G23: 2 | H23: Other | I23: user200@example.com
A24: EMP1021 | B24: Jane Smith | C24: HR | E24: 98922 | F24: 42155 | G24: 4 | I24: user77@example.com
A25: EMP1022 | B25: Eve Adams | C25: Finance | D25: India | E25: 38333 | F25: 42162 | G25: 5 | I25: user128@example.com
A26: EMP1023 | B26: Alice Brown | C26: Marketing | D26: UK | E26: 36515 | F26: 42169 | G26: 3 | H26: Male | I26: user149@example.com
A27: EMP1024 | B27: Sam Wilson | C27: Finance | E27: 91005 | F27: 42176 | G27: 1 | H27: Other | I27: user122@example.com
A28: EMP1025 | B28: Chris Lee | E28: 52272 | F28: 42183 | G28: 3 | I28: user41@example.com
A29: EMP1026 | B29: Eve Adams | C29: Sales | D29: Germany | E29: 76518 | F29: 42190 | G29: 2 | H29: Female | I29: user68@example.com
A30: EMP1027 | B30: Alice Brown | C30: IT | D30: UK | E30: 41448 | F30: 42197 | G30: 3 | H30: Other | I30: user103@example.com
A31: EMP1028 | B31: John Doe | C31: HR | D31: UK | E31: 49282 | F31: 42204 | G31: 2 | H31: Female | I31: user135@example.com
A32: EMP1029 | B32: Bob Johnson | C32: Marketing | D32: UK | E32: 92959 | F32: 42211 | G32: 5 | I32: user83@example.com
A33: EMP1030 | C33: Marketing | E33: 92259 | G33: 1 | H33: Unknown | I33: user109@example.com
A34: EMP1031 | B34: Eve Adams | C34: HR | D34: Germany | E34: 92299 | F34: 42225 | G34: 3 | H34: Male | I34: user143@example.com
A35: EMP1032 | B35: Sam Wilson | C35: HR | E35: 95586 | F35: 42232 | G35: 3 | H35: Other | I35: user190@example.com
A36: EMP1033 | B36: Chris Lee | D36: USA | E36: 95367 | F36: 42239 | H36: Male | I36: user136@example.com
A37: EMP1034 | B37: John Doe | C37: Sales | D37: Australia | E37: 79549 | F37: 42246 | G37: 3 | I37: user198@example.com
A38: EMP1035 | B38: Alice Brown | D38: UK | E38: 54463 | F38: 42253 | G38: 4 | H38: Male | I38: invalid_email
A39: EMP1036 | B39: Alice Brown | C39: IT | D39: USA | E39: 89781 | F39: 42260 | H39: Female | I39: user31@example.com
A40: EMP1037 | B40: Alice Brown | C40: HR | E40: 64796 | F40: 42267 | H40: Other | I40: user98@example.com
...

Sheet Day2_Data Cleaning
A1: DAY2 CHALLENGE-DATA CLEANING
A2: Employee ID | B2: Names | C2: Department | D2: Country | E2: Salary | F2: Date of Joining | G2: Performance Rating | H2: Gender | I2: Email | L2: KEY PROCEDURES UNDERTAKEN
A3: =CLEAN(TRIM(UPPER('Employee Details_GnDataset'!A3))) -> EMP1000 | B3: =CLEAN(TRIM(PROPER('Employee Details_GnDataset'!B3))) | C3: =CLEAN(TRIM(PROPER('Employee Details_GnDataset'!C3))) -> Finance | D3: =CLEAN(TRIM(PROPER('Employee Details_GnDataset'!D3))) | E3: ='Employee Details_GnDataset'!E3 -> N/A | F3: ='Employee Details_GnDataset'!F3 -> 0 | G3: =CLEAN(TRIM('Employee Details_GnDataset'!G3)) -> 2 | H3: =CLEAN(TRIM(PROPER('Employee Details_GnDataset'!H3))) -> Unknown | I3: =CLEAN(TRIM('Employee Details_GnDataset'!I3)) -> invalid_email | L3: Entire dataset is Formatted as Table, and Renamed the table as "Cleaned_Dataset"
A4: =CLEAN(TRIM(UPPER('Employee Details_GnDataset'!A4))) -> EMP1001 | B4: =CLEAN(TRIM(PROPER('Employee Details_GnDataset'!B4))) -> Eve Adams | C4: =CLEAN(TRIM(PROPER('Employee Details_GnDataset'!C4))) -> Hr | D4: =CLEAN(TRIM(PROPER('Employee Details_GnDataset'!D4))) -> Germany | E4: ='Employee Details_GnDataset'!E4 -> 54255 | F4: ='Employee Details_GnDataset'!F4 -> 42015 | G4: =CLEAN(TRIM('Employee Details_GnDataset'!G4)) -> 1 | H4: =CLEAN(TRIM(PROPER('Employee Details_GnDataset'!H4))) -> Other | I4: =CLEAN(TRIM('Employee Details_GnDataset'!I4)) -> user106@example.com
A5: =CLEAN(TRIM(UPPER('Employee Details_GnDataset'!A5))) -> EMP1002 | B5: =CLEAN(TRIM(PROPER('Employee Details_GnDataset'!B5))) -> Alice Brown | C5: =CLEAN(TRIM(PROPER('Employee Details_GnDataset'!C5))) -> Finance | D5: =CLEAN(TRIM(PROPER('Employee Details_GnDataset'!D5))) -> Germany | E5: ='Employee Details_GnDataset'!E5 -> 63184 | F5: ='Employee Details_GnDataset'!F5 -> 42022 | G5: =CLEAN(TRIM('Employee Details_GnDataset'!G5)) -> 2 | H5: =CLEAN(TRIM(PROPER('Employee Details_GnDataset'!H5))) | I5: =CLEAN(TRIM('Employee Details_GnDataset'!I5)) -> user176@example.com | L5: All the entities are cleaned by using CLEAN(), TRIM() and Formatted using PROPER() while importing from "Employee Details_GnDataset" except Salary & Date of Joining.
A6: =CLEAN(TRIM(UPPER('Employee Details_GnDataset'!A6))) -> EMP1003 | B6: =CLEAN(TRIM(PROPER('Employee Details_GnDataset'!B6))) -> John Doe | C6: =CLEAN(TRIM(PROPER('Employee Details_GnDataset'!C6))) -> Sales | D6: =CLEAN(TRIM(PROPER('Employee Details_GnDataset'!D6))) -> Usa | E6: ='Employee Details_GnDataset'!E6 -> 94406 | F6: ='Employee Details_GnDataset'!F6 -> 42029 | G6: =CLEAN(TRIM('Employee Details_GnDataset'!G6)) -> 1 | H6: =CLEAN(TRIM(PROPER('Employee Details_GnDataset'!H6))) -> Male | I6: =CLEAN(TRIM('Employee Details_GnDataset'!I6)) -> user168@example.com
A7: =CLEAN(TRIM(UPPER('Employee Details_GnDataset'!A7))) -> EMP1004 | B7: =CLEAN(TRIM(PROPER('Employee Details_GnDataset'!B7))) -> Jane Smith | C7: =CLEAN(TRIM(PROPER('Employee Details_GnDataset'!C7))) -> Sales | D7: =CLEAN(TRIM(PROPER('Employee Details_GnDataset'!D7))) -> Germany | E7: ='Employee Details_GnDataset'!E7 -> 64120 | F7: ='Employee Details_GnDataset'!F7 -> 42036 | G7: =CLEAN(TRIM('Employee Details_GnDataset'!G7)) -> 1 | H7: =CLEAN(TRIM(PROPER('Employee Details_GnDataset'!H7))) -> Male | I7: =CLEAN(TRIM('Employee Details_GnDataset'!I7)) -> user49@example.com
A8: =CLEAN(TRIM(UPPER('Employee Details_GnDataset'!A8))) -> EMP1005 | B8: =CLEAN(TRIM(PROPER('Employee Details_GnDataset'!B8))) -> Alice Brown | C8: =CLEAN(TRIM(PROPER('Employee Details_GnDataset'!C8))) -> It | D8: =CLEAN(TRIM(PROPER('Employee Details_GnDataset'!D8))) -> India | E8: ='Employee Details_GnDataset'!E8 -> 78421 | F8: ='Employee Details_GnDataset'!F8 -> 42043 | G8: =CLEAN(TRIM('Employee Details_GnDataset'!G8)) -> 2 | H8: =CLEAN(TRIM(PROPER('Employee Details_GnDataset'!H8))) -> Female | I8: =CLEAN(TRIM('Employee Details_GnDataset'!I8)) -> user24@example.com | L8: Employee ID,Names,Department,Country,Gender,Email columns are formatted to Text Data type.
A9: =CLEAN(TRIM(UPPER('Employee Details_GnDataset'!A9))) -> EMP1006 | B9: =CLEAN(TRIM(PROPER('Employee Details_GnDataset'!B9))) -> Sam Wilson | C9: =CLEAN(TRIM(PROPER('Employee Details_GnDataset'!C9))) -> Sales | D9: =CLEAN(TRIM(PROPER('Employee Details_GnDataset'!D9))) | E9: ='Employee Details_GnDataset'!E9 -> 67721 | F9: ='Employee Details_GnDataset'!F9 -> 42050 | G9: =CLEAN(TRIM('Employee Details_GnDataset'!G9)) | H9: =CLEAN(TRIM(PROPER('Employee Details_GnDataset'!H9))) -> Male | I9: =CLEAN(TRIM('Employee Details_GnDataset'!I9)) -> user168@example.com
A10: =CLEAN(TRIM(UPPER('Employee Details_GnDataset'!A10))) -> EMP1007 | B10: =CLEAN(TRIM(PROPER('Employee Details_GnDataset'!B10))) -> Chris Lee | C10: =CLEAN(TRIM(PROPER('Employee Details_GnDataset'!C10))) -> Marketing | D10: =CLEAN(TRIM(PROPER('Employee Details_GnDataset'!D10))) | E10: ='Employee Details_GnDataset'!E10 -> 35364 | F10: ='Employee Details_GnDataset'!F10 -> 42057 | G10: =CLEAN(TRIM('Employee Details_GnDataset'!G10)) -> 2 | H10: =CLEAN(TRIM(PROPER('Employee Details_GnDataset'!H10))) -> Other | I10: =CLEAN(TRIM('Employee Details_GnDataset'!I10)) -> user26@example.com | L10: Salary column is imported first and stored as Currency data type as it contains two different data types in single column.
A11: =CLEAN(TRIM(UPPER('Employee Details_GnDataset'!A11))) -> EMP1008 | B11: =CLEAN(TRIM(PROPER('Employee Details_GnDataset'!B11))) -> Alice Brown | C11: =CLEAN(TRIM(PROPER('Employee Details_GnDataset'!C11))) -> It | D11: =CLEAN(TRIM(PROPER('Employee Details_GnDataset'!D11))) -> Germany | E11: ='Employee Details_GnDataset'!E11 -> 97881 | F11: ='Employee Details_GnDataset'!F11 -> 42064 | G11: =CLEAN(TRIM('Employee Details_GnDataset'!G11)) | H11: =CLEAN(TRIM(PROPER('Employee Details_GnDataset'!H11))) -> Female | I11: =CLEAN(TRIM('Employee Details_GnDataset'!I11)) -> user25@example.com
A12: =CLEAN(TRIM(UPPER('Employee Details_GnDataset'!A12))) -> EMP1009 | B12: =CLEAN(TRIM(PROPER('Employee Details_GnDataset'!B12))) -> Chris Lee | C12: =CLEAN(TRIM(PROPER('Employee Details_GnDataset'!C12))) -> Hr | D12: =CLEAN(TRIM(PROPER('Employee Details_GnDataset'!D12))) -> Uk | E12: ='Employee Details_GnDataset'!E12 -> 91846 | F12: ='Employee Details_GnDataset'!F12 -> 42071 | G12: =CLEAN(TRIM('Employee Details_GnDataset'!G12)) | H12: =CLEAN(TRIM(PROPER('Employee Details_GnDataset'!H12))) -> Male | I12: =CLEAN(TRIM('Employee Details_GnDataset'!I12)) -> user153@example.com | L12: The Date of Joining column is stored as a Date data type; blank cells were automatically replaced with the default system date 00-01-1900.
A13: =CLEAN(TRIM(UPPER('Employee Details_GnDataset'!A13))) -> EMP1010 | B13: =CLEAN(TRIM(PROPER('Employee Details_GnDataset'!B13))) -> Sam Wilson | C13: =CLEAN(TRIM(PROPER('Employee Details_GnDataset'!C13))) -> Finance | D13: =CLEAN(TRIM(PROPER('Employee Details_GnDataset'!D13))) -> Uk | E13: ='Employee Details_GnDataset'!E13 -> 64247 | F13: ='Employee Details_GnDataset'!F13 -> 42078 | G13: =CLEAN(TRIM('Employee Details_GnDataset'!G13)) -> 1 | H13: =CLEAN(TRIM(PROPER('Employee Details_GnDataset'!H13))) -> Female | I13: =CLEAN(TRIM('Employee Details_GnDataset'!I13)) -> user18@example.com
A14: =CLEAN(TRIM(UPPER('Employee Details_GnDataset'!A14))) -> EMP1011 | B14: =CLEAN(TRIM(PROPER('Employee Details_GnDataset'!B14))) -> Sam Wilson | C14: =CLEAN(TRIM(PROPER('Employee Details_GnDataset'!C14))) -> It | D14: =CLEAN(TRIM(PROPER('Employee Details_GnDataset'!D14))) -> Usa | E14: ='Employee Details_GnDataset'!E14 -> 91180 | F14: ='Employee Details_GnDataset'!F14 -> 42085 | G14: =CLEAN(TRIM('Employee Details_GnDataset'!G14)) -> 5 | H14: =CLEAN(TRIM(PROPER('Employee Details_GnDataset'!H14))) -> Male | I14: =CLEAN(TRIM('Employee Details_GnDataset'!I14)) -> user1@example.com
A15: =CLEAN(TRIM(UPPER('Employee Details_GnDataset'!A15))) -> EMP1012 | B15: =CLEAN(TRIM(PROPER('Employee Details_GnDataset'!B15))) -> Bob Johnson | C15: =CLEAN(TRIM(PROPER('Employee Details_GnDataset'!C15))) -> Sales | D15: =CLEAN(TRIM(PROPER('Employee Details_GnDataset'!D15))) | E15: ='Employee Details_GnDataset'!E15 -> 96418 | F15: ='Employee Details_GnDataset'!F15 -> 42092 | G15: =CLEAN(TRIM('Employee Details_GnDataset'!G15)) -> 5 | H15: =CLEAN(TRIM(PROPER('Employee Details_GnDataset'!H15))) -> Male | I15: =CLEAN(TRIM('Employee Details_GnDataset'!I15)) -> user106@example.com
A16: =CLEAN(TRIM(UPPER('Employee Details_GnDataset'!A16))) -> EMP1013 | B16: =CLEAN(TRIM(PROPER('Employee Details_GnDataset'!B16))) -> Sam Wilson | C16: =CLEAN(TRIM(PROPER('Employee Details_GnDataset'!C16))) | D16: =CLEAN(TRIM(PROPER('Employee Details_GnDataset'!D16))) -> India | E16: ='Employee Details_GnDataset'!E16 -> 62158 | F16: ='Employee Details_GnDataset'!F16 -> 42099 | G16: =CLEAN(TRIM('Employee Details_GnDataset'!G16)) -> 4 | H16: =CLEAN(TRIM(PROPER('Employee Details_GnDataset'!H16))) | I16: =CLEAN(TRIM('Employee Details_GnDataset'!I16)) -> user180@example.com
A17: =CLEAN(TRIM(UPPER('Employee Details_GnDataset'!A17))) -> EMP1014 | B17: =CLEAN(TRIM(PROPER('Employee Details_GnDataset'!B17))) -> Jane Smith | C17: =CLEAN(TRIM(PROPER('Employee Details_GnDataset'!C17))) -> Hr | D17: =CLEAN(TRIM(PROPER('Employee Details_GnDataset'!D17))) | E17: ='Employee Details_GnDataset'!E17 -> 59894 | F17: ='Employee Details_GnDataset'!F17 -> 42106 | G17: =CLEAN(TRIM('Employee Details_GnDataset'!G17)) -> 2 | H17: =CLEAN(TRIM(PROPER('Employee Details_GnDataset'!H17))) -> Male | I17: =CLEAN(TRIM('Employee Details_GnDataset'!I17)) -> user184@example.com
A18: =CLEAN(TRIM(UPPER('Employee Details_GnDataset'!A18))) -> EMP1015 | B18: =CLEAN(TRIM(PROPER('Employee Details_GnDataset'!B18))) | C18: =CLEAN(TRIM(PROPER('Employee Details_GnDataset'!C18))) -> It | D18: =CLEAN(TRIM(PROPER('Employee Details_GnDataset'!D18))) -> India | E18: ='Employee Details_GnDataset'!E18 -> 92443 | F18: ='Employee Details_GnDataset'!F18 -> 42113 | G18: =CLEAN(TRIM('Employee Details_GnDataset'!G18)) -> 3 | H18: =CLEAN(TRIM(PROPER('Employee Details_GnDataset'!H18))) -> Other | I18: =CLEAN(TRIM('Employee Details_GnDataset'!I18)) -> user3@example.com
A19: =CLEAN(TRIM(UPPER('Employee Details_GnDataset'!A19))) -> EMP1016 | B19: =CLEAN(TRIM(PROPER('Employee Details_GnDataset'!B19))) -> Bob Johnson | C19: =CLEAN(TRIM(PROPER('Employee Details_GnDataset'!C19))) | D19: =CLEAN(TRIM(PROPER('Employee Details_GnDataset'!D19))) -> Germany | E19: ='Employee Details_GnDataset'!E19 -> 90271 | F19: ='Employee Details_GnDataset'!F19 -> 42120 | G19: =CLEAN(TRIM('Employee Details_GnDataset'!G19)) | H19: =CLEAN(TRIM(PROPER('Employee Details_GnDataset'!H19))) | I19: =CLEAN(TRIM('Employee Details_GnDataset'!I19)) -> user64@example.com
A20: =CLEAN(TRIM(UPPER('Employee Details_GnDataset'!A20))) -> EMP1017 | B20: =CLEAN(TRIM(PROPER('Employee Details_GnDataset'!B20))) -> Jane Smith | C20: =CLEAN(TRIM(PROPER('Employee Details_GnDataset'!C20))) -> Finance | D20: =CLEAN(TRIM(PROPER('Employee Details_GnDataset'!D20))) -> Australia | E20: ='Employee Details_GnDataset'!E20 -> 41341 | F20: ='Employee Details_GnDataset'!F20 -> 42127 | G20: =CLEAN(TRIM('Employee Details_GnDataset'!G20)) -> 1 | H20: =CLEAN(TRIM(PROPER('Employee Details_GnDataset'!H20))) -> Other | I20: =CLEAN(TRIM('Employee Details_GnDataset'!I20)) -> user38@example.com
A21: =CLEAN(TRIM(UPPER('Employee Details_GnDataset'!A21))) -> EMP1018 | B21: =CLEAN(TRIM(PROPER('Employee Details_GnDataset'!B21))) -> Alice Brown | C21: =CLEAN(TRIM(PROPER('Employee Details_GnDataset'!C21))) -> Finance | D21: =CLEAN(TRIM(PROPER('Employee Details_GnDataset'!D21))) -> Uk | E21: ='Employee Details_GnDataset'!E21 -> 73602 | F21: ='Employee Details_GnDataset'!F21 -> 42134 | G21: =CLEAN(TRIM('Employee Details_GnDataset'!G21)) | H21: =CLEAN(TRIM(PROPER('Employee Details_GnDataset'!H21))) | I21: =CLEAN(TRIM('Employee Details_GnDataset'!I21)) -> user96@example.com
A22: =CLEAN(TRIM(UPPER('Employee Details_GnDataset'!A22))) -> EMP1019 | B22: =CLEAN(TRIM(PROPER('Employee Details_GnDataset'!B22))) -> Eve Adams | C22: =CLEAN(TRIM(PROPER('Employee Details_GnDataset'!C22))) | D22: =CLEAN(TRIM(PROPER('Employee Details_GnDataset'!D22))) -> India | E22: ='Employee Details_GnDataset'!E22 -> 67531 | F22: ='Employee Details_GnDataset'!F22 -> 42141 | G22: =CLEAN(TRIM('Employee Details_GnDataset'!G22)) -> 5 | H22: =CLEAN(TRIM(PROPER('Employee Details_GnDataset'!H22))) -> Female | I22: =CLEAN(TRIM('Employee Details_GnDataset'!I22)) -> user151@example.com
A23: =CLEAN(TRIM(UPPER('Employee Details_GnDataset'!A23))) -> EMP1020 | B23: =CLEAN(TRIM(PROPER('Employee Details_GnDataset'!B23))) -> Jane Smith | C23: =CLEAN(TRIM(PROPER('Employee Details_GnDataset'!C23))) -> Hr | D23: =CLEAN(TRIM(PROPER('Employee Details_GnDataset'!D23))) -> Usa | E23: ='Employee Details_GnDataset'!E23 -> N/A | F23: ='Employee Details_GnDataset'!F23 -> 42148 | G23: =CLEAN(TRIM('Employee Details_GnDataset'!G23)) -> 2 | H23: =CLEAN(TRIM(PROPER('Employee Details_GnDataset'!H23))) -> Other | I23: =CLEAN(TRIM('Employee Details_GnDataset'!I23)) -> user200@example.com
A24: =CLEAN(TRIM(UPPER('Employee Details_GnDataset'!A24))) -> EMP1021 | B24: =CLEAN(TRIM(PROPER('Employee Details_GnDataset'!B24))) -> Jane Smith | C24: =CLEAN(TRIM(PROPER('Employee Details_GnDataset'!C24))) -> Hr | D24: =CLEAN(TRIM(PROPER('Employee Details_GnDataset'!D24))) | E24: ='Employee Details_GnDataset'!E24 -> 98922 | F24: ='Employee Details_GnDataset'!F24 -> 42155 | G24: =CLEAN(TRIM('Employee Details_GnDataset'!G24)) -> 4 | H24: =CLEAN(TRIM(PROPER('Employee Details_GnDataset'!H24))) | I24: =CLEAN(TRIM('Employee Details_GnDataset'!I24)) -> user77@example.com
... A152: =CLEAN(TRIM(UPPER('Employee Details_GnDataset'!A152))) -> EMP1149 | B152: =CLEAN(TRIM(PROPER('Employee Details_GnDataset'!B152))) -> Sam Wilson | C152: =CLEAN(TRIM(PROPER('Employee Details_GnDataset'!C152))) -> Marketing | D152: =CLEAN(TRIM(PROPER('Employee Details_GnDataset'!D152))) -> India | E152: ='Employee Details_GnDataset'!E152 -> 98475 | F152: ='Employee Details_GnDataset'!F152 -> 43051 | G152: =CLEAN(TRIM('Employee Details_GnDataset'!G152)) -> 5 | H152: =CLEAN(TRIM(PROPER('Employee Details_GnDataset'!H152))) -> Other | I152: =CLEAN(TRIM('Employee Details_GnDataset'!I152)) -> user30@example.com
