Workbook

Sheet Raw data for day3
A1: DAY 2 CHALLENGE- DATA CLEANING
A3: Employee ID | B3: Names | C3: Department | D3: Country | E3: Salary | F3: Date of Joining | G3: Date of Joining Year | H3: Performance Rating | I3: Gender | J3: Email
A4: EMP1000 | C4: Finance | E4: N/A | G4: =YEAR(Cleaned_Data4[[#This Row],[Date of Joining]]) -> 1900 | H4: 2 | I4: Unknown | J4: invalid_email
A5: EMP1001 | B5: Eve Adams | C5: HR | D5: Germany | E5: 54255 | F5: 42015 | G5: =YEAR(F5) -> 2015 | H5: 1 | I5: Other | J5: user106@example.com
A6: EMP1002 | B6: Alice Brown | C6: Finance | D6: Germany | E6: 63184 | F6: 42022 | G6: =YEAR(F6) -> 2015 | H6: 2 | J6: user176@example.com
A7: EMP1003 | B7: John Doe | C7: Sales | D7: USA | E7: 94406 | F7: 42029 | G7: =YEAR(F7) -> 2015 | H7: 1 | I7: Male | J7: user168@example.com
A8: EMP1004 | B8: Jane Smith | C8: Sales | D8: Germany | E8: 64120 | F8: 42036 | G8: =YEAR(F8) -> 2015 | H8: 1 | I8: Male | J8: user49@example.com
A9: EMP1005 | B9: Alice Brown | C9: IT | D9: India | E9: 78421 | F9: 42043 | G9: =YEAR(F9) -> 2015 | H9: 2 | I9: Female | J9: user24@example.com
A10: EMP1006 | B10: Sam Wilson | C10: Sales | E10: 67721 | F10: 42050 | G10: =YEAR(F10) -> 2015 | I10: Male | J10: user168@example.com
A11: EMP1007 | B11: Chris Lee | C11: Marketing | E11: 35364 | F11: 42057 | G11: =YEAR(F11) -> 2015 | H11: 2 | I11: Other | J11: user26@example.com
A12: EMP1008 | B12: Alice Brown | C12: IT | D12: Germany | E12: 97881 | F12: 42064 | G12: =YEAR(F12) -> 2015 | I12: Female | J12: user25@example.com
A13: EMP1009 | B13: Chris Lee | C13: HR | D13: UK | E13: 91846 | F13: 42071 | G13: =YEAR(F13) -> 2015 | I13: Male | J13: user153@example.com
A14: EMP1010 | B14: Sam Wilson | C14: Finance | D14: UK | E14: 64247 | F14: 42078 | G14: =YEAR(F14) -> 2015 | H14: 1 | I14: Female | J14: user18@example.com
A15: EMP1011 | B15: Sam Wilson | C15: IT | D15: USA | E15: 91180 | F15: 42085 | G15: =YEAR(F15) -> 2015 | H15: 5 | I15: Male | J15: user1@example.com
A16: EMP1012 | B16: Bob Johnson | C16: Sales | E16: 96418 | F16: 42092 | G16: =YEAR(F16) -> 2015 | H16: 5 | I16: Male | J16: user106@example.com
A17: EMP1013 | B17: Sam Wilson | D17: India | E17: 62158 | F17: 42099 | G17: =YEAR(F17) -> 2015 | H17: 4 | J17: user180@example.com
A18: EMP1014 | B18: Jane Smith | C18: HR | E18: 59894 | F18: 42106 | G18: =YEAR(F18) -> 2015 | H18: 2 | I18: Male | J18: user184@example.com
A19: EMP1015 | C19: IT | D19: India | E19: 92443 | F19: 42113 | G19: =YEAR(F19) -> 2015 | H19: 3 | I19: Other | J19: user3@example.com
A20: EMP1016 | B20: Bob Johnson | D20: Germany | E20: 90271 | F20: 42120 | G20: =YEAR(F20) -> 2015 | J20: user64@example.com
A21: EMP1017 | B21: Jane Smith | C21: Finance | D21: Australia | E21: 41341 | F21: 42127 | G21: =YEAR(F21) -> 2015 | H21: 1 | I21: Other | J21: user38@example.com
A22: EMP1018 | B22: Alice Brown | C22: Finance | D22: UK | E22: 73602 | F22: 42134 | G22: =YEAR(F22) -> 2015 | J22: user96@example.com
A23: EMP1019 | B23: Eve Adams | D23: India | E23: 67531 | F23: 42141 | G23: =YEAR(F23) -> 2015 | H23: 5 | I23: Female | J23: user151@example.com
A24: EMP1020 | B24: Jane Smith | C24: HR | D24: USA | E24: N/A | F24: 42148 | G24: =YEAR(F24) -> 2015 | H24: 2 | I24: Other | J24: user200@example.com
A25: EMP1021 | B25: Jane Smith | C25: HR | E25: 98922 | F25: 42155 | G25: =YEAR(F25) -> 2015 | H25: 4 | J25: user77@example.com
A26: EMP1022 | B26: Eve Adams | C26: Finance | D26: India | E26: 38333 | F26: 42162 | G26: =YEAR(F26) -> 2015 | H26: 5 | J26: user128@example.com
A27: EMP1023 | B27: Alice Brown | C27: Marketing | D27: UK | E27: 36515 | F27: 42169 | G27: =YEAR(F27) -> 2015 | H27: 3 | I27: Male | J27: user149@example.com
A28: EMP1024 | B28: Sam Wilson | C28: Finance | E28: 91005 | F28: 42176 | G28: =YEAR(F28) -> 2015 | H28: 1 | I28: Other | J28: user122@example.com
A29: EMP1025 | B29: Chris Lee | E29: 52272 | F29: 42183 | G29: =YEAR(F29) -> 2015 | H29: 3 | J29: user41@example.com
A30: EMP1026 | B30: Eve Adams | C30: Sales | D30: Germany | E30: 76518 | F30: 42190 | G30: =YEAR(F30) -> 2015 | H30: 2 | I30: Female | J30: user68@example.com
A31: EMP1027 | B31: Alice Brown | C31: IT | D31: UK | E31: 41448 | F31: 42197 | G31: =YEAR(F31) -> 2015 | H31: 3 | I31: Other | J31: user103@example.com
A32: EMP1028 | B32: John Doe | C32: HR | D32: UK | E32: 49282 | F32: 42204 | G32: =YEAR(F32) -> 2015 | H32: 2 | I32: Female | J32: user135@example.com
A33: EMP1029 | B33: Bob Johnson | C33: Marketing | D33: UK | E33: 92959 | F33: 42211 | G33: =YEAR(F33) -> 2015 | H33: 5 | J33: user83@example.com
A34: EMP1030 | C34: Marketing | E34: 92259 | G34: =YEAR(F34) -> 1900 | H34: 1 | I34: Unknown | J34: user109@example.com
A35: EMP1031 | B35: Eve Adams | C35: HR | D35: Germany | E35: 92299 | F35: 42225 | G35: =YEAR(F35) -> 2015 | H35: 3 | I35: Male | J35: user143@example.com
A36: EMP1032 | B36: Sam Wilson | C36: HR | E36: 95586 | F36: 42232 | G36: =YEAR(F36) -> 2015 | H36: 3 | I36: Other | J36: user190@example.com
A37: EMP1033 | B37: Chris Lee | D37: USA | E37: 95367 | F37: 42239 | G37: =YEAR(F37) -> 2015 | I37: Male | J37: user136@example.com
A38: EMP1034 | B38: John Doe | C38: Sales | D38: Australia | E38: 79549 | F38: 42246 | G38: =YEAR(F38) -> 2015 | H38: 3 | J38: user198@example.com
A39: EMP1035 | B39: Alice Brown | D39: UK | E39: 54463 | F39: 42253 | G39: =YEAR(F39) -> 2015 | H39: 4 | I39: Male | J39: invalid_email
A40: EMP1036 | B40: Alice Brown | C40: IT | D40: USA | E40: 89781 | F40: 42260 | G40: =YEAR(F40) -> 2015 | I40: Female | J40: user31@example.com
A41: EMP1037 | B41: Alice Brown | C41: HR | E41: 64796 | F41: 42267 | G41: =YEAR(F41) -> 2015 | I41: Other | J41: user98@example.com
...

Sheet Day3
A1: DAY3 CHALLENGE-IMPUTATION & BASIC FUNCTION (Part-1)
A2: IMPUTATION | K2: Utilize UNIQUE COUNTA, COUNTBLANK,COUNTIF & SUM Functions | O2: DESCRIPTION OF USING FUNCTIONS | U2: DESCRIPTION OF IMPUTATION
A3: Employee ID | B3: Names | C3: Department | D3: Country | E3: Salary | F3: Date of Joining | G3: Performance Rating | H3: Gender | I3: Email
A4: =Cleaned_Data4[[#This Row],[Employee ID]] -> EMP1000 | B4: =IF(Cleaned_Data4[[#This Row],[Names]]="","Un-known",Cleaned_Data4[[#This Row],[Names]]) -> Un-known | C4: =IF(Cleaned_Data4[[#This Row],[Department]]="","Un-known",Cleaned_Data4[[#This Row],[Department]]) -> Finance | D4: =IF(Cleaned_Data4[[#This Row],[Country]]="","Un-known",Cleaned_Data4[[#This Row],[Country]]) -> Un-known | E4: =IF(Cleaned_Data4[[#This Row],[Salary]]="N/A","0",Cleaned_Data4[[#This Row],[Salary]]) -> 0 | F4: =IF(Cleaned_Data4[[#This Row],[Date of Joining]]="","Un-known",Cleaned_Data4[[#This Row],[Date of Joining]]) -> Un-known | G4: =IF(Cleaned_Data4[[#This Row],[Performance Rating]]="","N/A",Cleaned_Data4[[#This Row],[Performance Rating]]) -> 2 | H4: =IF(Cleaned_Data4[[#This Row],[Gender]]="","Un-known",Cleaned_Data4[[#This Row],[Gender]]) -> Unknown | I4: =IF(Cleaned_Data4[[#This Row],[Email]]="","invalid_email",Cleaned_Data4[[#This Row],[Email]]) -> invalid_email | K4: Total No.of Employee | M4: =COUNTA(Table47[Employee ID]) -> 150 | O4: COUNTA() used to count total number of Employees | U4: Column Names | V4: Imputed Values
A5: =Cleaned_Data4[[#This Row],[Employee ID]] -> EMP1001 | B5: =IF(Cleaned_Data4[[#This Row],[Names]]="","Un-known",Cleaned_Data4[[#This Row],[Names]]) -> Eve Adams | C5: =IF(Cleaned_Data4[[#This Row],[Department]]="","Un-known",Cleaned_Data4[[#This Row],[Department]]) -> HR | D5: =IF(Cleaned_Data4[[#This Row],[Country]]="","Un-known",Cleaned_Data4[[#This Row],[Country]]) -> Germany | E5: =IF(Cleaned_Data4[[#This Row],[Salary]]="N/A","0",Cleaned_Data4[[#This Row],[Salary]]) -> 54255 | F5: =IF(Cleaned_Data4[[#This Row],[Date of Joining]]="","Un-known",Cleaned_Data4[[#This Row],[Date of Joining]]) -> 42015 | G5: =IF(Cleaned_Data4[[#This Row],[Performance Rating]]="","N/A",Cleaned_Data4[[#This Row],[Performance Rating]]) -> 1 | H5: =IF(Cleaned_Data4[[#This Row],[Gender]]="","Un-known",Cleaned_Data4[[#This Row],[Gender]]) -> Other | I5: =IF(Cleaned_Data4[[#This Row],[Email]]="","invalid_email",Cleaned_Data4[[#This Row],[Email]]) -> user106@example.com
A6: =Cleaned_Data4[[#This Row],[Employee ID]] -> EMP1002 | B6: =IF(Cleaned_Data4[[#This Row],[Names]]="","Un-known",Cleaned_Data4[[#This Row],[Names]]) -> Alice Brown | C6: =IF(Cleaned_Data4[[#This Row],[Department]]="","Un-known",Cleaned_Data4[[#This Row],[Department]]) -> Finance | D6: =IF(Cleaned_Data4[[#This Row],[Country]]="","Un-known",Cleaned_Data4[[#This Row],[Country]]) -> Germany | E6: =IF(Cleaned_Data4[[#This Row],[Salary]]="N/A","0",Cleaned_Data4[[#This Row],[Salary]]) -> 63184 | F6: =IF(Cleaned_Data4[[#This Row],[Date of Joining]]="","Un-known",Cleaned_Data4[[#This Row],[Date of Joining]]) -> 42022 | G6: =IF(Cleaned_Data4[[#This Row],[Performance Rating]]="","N/A",Cleaned_Data4[[#This Row],[Performance Rating]]) -> 2 | H6: =IF(Cleaned_Data4[[#This Row],[Gender]]="","Un-known",Cleaned_Data4[[#This Row],[Gender]]) -> Un-known | I6: =IF(Cleaned_Data4[[#This Row],[Email]]="","invalid_email",Cleaned_Data4[[#This Row],[Email]]) -> user176@example.com | K6: Unique values in DEPARTMENT column | U6: Names | V6: Un-known
A7: =Cleaned_Data4[[#This Row],[Employee ID]] -> EMP1003 | B7: =IF(Cleaned_Data4[[#This Row],[Names]]="","Un-known",Cleaned_Data4[[#This Row],[Names]]) -> John Doe | C7: =IF(Cleaned_Data4[[#This Row],[Department]]="","Un-known",Cleaned_Data4[[#This Row],[Department]]) -> Sales | D7: =IF(Cleaned_Data4[[#This Row],[Country]]="","Un-known",Cleaned_Data4[[#This Row],[Country]]) -> USA | E7: =IF(Cleaned_Data4[[#This Row],[Salary]]="N/A","0",Cleaned_Data4[[#This Row],[Salary]]) -> 94406 | F7: =IF(Cleaned_Data4[[#This Row],[Date of Joining]]="","Un-known",Cleaned_Data4[[#This Row],[Date of Joining]]) -> 42029 | G7: =IF(Cleaned_Data4[[#This Row],[Performance Rating]]="","N/A",Cleaned_Data4[[#This Row],[Performance Rating]]) -> 1 | H7: =IF(Cleaned_Data4[[#This Row],[Gender]]="","Un-known",Cleaned_Data4[[#This Row],[Gender]]) -> Male | I7: =IF(Cleaned_Data4[[#This Row],[Email]]="","invalid_email",Cleaned_Data4[[#This Row],[Email]]) -> user168@example.com | U7: Department | V7: Un-known
A8: =Cleaned_Data4[[#This Row],[Employee ID]] -> EMP1004 | B8: =IF(Cleaned_Data4[[#This Row],[Names]]="","Un-known",Cleaned_Data4[[#This Row],[Names]]) -> Jane Smith | C8: =IF(Cleaned_Data4[[#This Row],[Department]]="","Un-known",Cleaned_Data4[[#This Row],[Department]]) -> Sales | D8: =IF(Cleaned_Data4[[#This Row],[Country]]="","Un-known",Cleaned_Data4[[#This Row],[Country]]) -> Germany | E8: =IF(Cleaned_Data4[[#This Row],[Salary]]="N/A","0",Cleaned_Data4[[#This Row],[Salary]]) -> 64120 | F8: =IF(Cleaned_Data4[[#This Row],[Date of Joining]]="","Un-known",Cleaned_Data4[[#This Row],[Date of Joining]]) -> 42036 | G8: =IF(Cleaned_Data4[[#This Row],[Performance Rating]]="","N/A",Cleaned_Data4[[#This Row],[Performance Rating]]) -> 1 | H8: =IF(Cleaned_Data4[[#This Row],[Gender]]="","Un-known",Cleaned_Data4[[#This Row],[Gender]]) -> Male | I8: =IF(Cleaned_Data4[[#This Row],[Email]]="","invalid_email",Cleaned_Data4[[#This Row],[Email]]) -> user49@example.com | K8: Department Names | L8: No. of Employee in Each Department | U8: Country | V8: Un-known
A9: =Cleaned_Data4[[#This Row],[Employee ID]] -> EMP1005 | B9: =IF(Cleaned_Data4[[#This Row],[Names]]="","Un-known",Cleaned_Data4[[#This Row],[Names]]) -> Alice Brown | C9: =IF(Cleaned_Data4[[#This Row],[Department]]="","Un-known",Cleaned_Data4[[#This Row],[Department]]) -> IT | D9: =IF(Cleaned_Data4[[#This Row],[Country]]="","Un-known",Cleaned_Data4[[#This Row],[Country]]) -> India | E9: =IF(Cleaned_Data4[[#This Row],[Salary]]="N/A","0",Cleaned_Data4[[#This Row],[Salary]]) -> 78421 | F9: =IF(Cleaned_Data4[[#This Row],[Date of Joining]]="","Un-known",Cleaned_Data4[[#This Row],[Date of Joining]]) -> 42043 | G9: =IF(Cleaned_Data4[[#This Row],[Performance Rating]]="","N/A",Cleaned_Data4[[#This Row],[Performance Rating]]) -> 2 | H9: =IF(Cleaned_Data4[[#This Row],[Gender]]="","Un-known",Cleaned_Data4[[#This Row],[Gender]]) -> Female | I9: =IF(Cleaned_Data4[[#This Row],[Email]]="","invalid_email",Cleaned_Data4[[#This Row],[Email]]) -> user24@example.com | O9: UNIQUE() utilised to determine the distinct values in Depatment column. | U9: Salary | V9: 0
A10: =Cleaned_Data4[[#This Row],[Employee ID]] -> EMP1006 | B10: =IF(Cleaned_Data4[[#This Row],[Names]]="","Un-known",Cleaned_Data4[[#This Row],[Names]]) -> Sam Wilson | C10: =IF(Cleaned_Data4[[#This Row],[Department]]="","Un-known",Cleaned_Data4[[#This Row],[Department]]) -> Sales | D10: =IF(Cleaned_Data4[[#This Row],[Country]]="","Un-known",Cleaned_Data4[[#This Row],[Country]]) -> Un-known | E10: =IF(Cleaned_Data4[[#This Row],[Salary]]="N/A","0",Cleaned_Data4[[#This Row],[Salary]]) -> 67721 | F10: =IF(Cleaned_Data4[[#This Row],[Date of Joining]]="","Un-known",Cleaned_Data4[[#This Row],[Date of Joining]]) -> 42050 | G10: =IF(Cleaned_Data4[[#This Row],[Performance Rating]]="","N/A",Cleaned_Data4[[#This Row],[Performance Rating]]) -> N/A | H10: =IF(Cleaned_Data4[[#This Row],[Gender]]="","Un-known",Cleaned_Data4[[#This Row],[Gender]]) -> Male | I10: =IF(Cleaned_Data4[[#This Row],[Email]]="","invalid_email",Cleaned_Data4[[#This Row],[Email]]) -> user168@example.com | K10: {=_xlfn.UNIQUE(Cleaned_Data4[Department])} -> Finance | L10: =COUNTIF('Raw data for day3'!C4:C153,K10) -> 22 | U10: Date of Joining | V10: Un-known
A11: =Cleaned_Data4[[#This Row],[Employee ID]] -> EMP1007 | B11: =IF(Cleaned_Data4[[#This Row],[Names]]="","Un-known",Cleaned_Data4[[#This Row],[Names]]) -> Chris Lee | C11: =IF(Cleaned_Data4[[#This Row],[Department]]="","Un-known",Cleaned_Data4[[#This Row],[Department]]) -> Marketing | D11: =IF(Cleaned_Data4[[#This Row],[Country]]="","Un-known",Cleaned_Data4[[#This Row],[Country]]) -> Un-known | E11: =IF(Cleaned_Data4[[#This Row],[Salary]]="N/A","0",Cleaned_Data4[[#This Row],[Salary]]) -> 35364 | F11: =IF(Cleaned_Data4[[#This Row],[Date of Joining]]="","Un-known",Cleaned_Data4[[#This Row],[Date of Joining]]) -> 42057 | G11: =IF(Cleaned_Data4[[#This Row],[Performance Rating]]="","N/A",Cleaned_Data4[[#This Row],[Performance Rating]]) -> 2 | H11: =IF(Cleaned_Data4[[#This Row],[Gender]]="","Un-known",Cleaned_Data4[[#This Row],[Gender]]) -> Other | I11: =IF(Cleaned_Data4[[#This Row],[Email]]="","invalid_email",Cleaned_Data4[[#This Row],[Email]]) -> user26@example.com | K11: HR | L11: =COUNTIF('Raw data for day3'!$C$4:$C$153,K11) -> 24 | O11: COUNTIF() was used to identify No. of employees in each deaprtment. | U11: Performance Rating | V11: N/A
A12: =Cleaned_Data4[[#This Row],[Employee ID]] -> EMP1008 | B12: =IF(Cleaned_Data4[[#This Row],[Names]]="","Un-known",Cleaned_Data4[[#This Row],[Names]]) -> Alice Brown | C12: =IF(Cleaned_Data4[[#This Row],[Department]]="","Un-known",Cleaned_Data4[[#This Row],[Department]]) -> IT | D12: =IF(Cleaned_Data4[[#This Row],[Country]]="","Un-known",Cleaned_Data4[[#This Row],[Country]]) -> Germany | E12: =IF(Cleaned_Data4[[#This Row],[Salary]]="N/A","0",Cleaned_Data4[[#This Row],[Salary]]) -> 97881 | F12: =IF(Cleaned_Data4[[#This Row],[Date of Joining]]="","Un-known",Cleaned_Data4[[#This Row],[Date of Joining]]) -> 42064 | G12: =IF(Cleaned_Data4[[#This Row],[Performance Rating]]="","N/A",Cleaned_Data4[[#This Row],[Performance Rating]]) -> N/A | H12: =IF(Cleaned_Data4[[#This Row],[Gender]]="","Un-known",Cleaned_Data4[[#This Row],[Gender]]) -> Female | I12: =IF(Cleaned_Data4[[#This Row],[Email]]="","invalid_email",Cleaned_Data4[[#This Row],[Email]]) -> user25@example.com | K12: Sales | L12: =COUNTIF('Raw data for day3'!$C$4:$C$153,K12) -> 26 | U12: Gender | V12: Un-known
A13: =Cleaned_Data4[[#This Row],[Employee ID]] -> EMP1009 | B13: =IF(Cleaned_Data4[[#This Row],[Names]]="","Un-known",Cleaned_Data4[[#This Row],[Names]]) -> Chris Lee | C13: =IF(Cleaned_Data4[[#This Row],[Department]]="","Un-known",Cleaned_Data4[[#This Row],[Department]]) -> HR | D13: =IF(Cleaned_Data4[[#This Row],[Country]]="","Un-known",Cleaned_Data4[[#This Row],[Country]]) -> UK | E13: =IF(Cleaned_Data4[[#This Row],[Salary]]="N/A","0",Cleaned_Data4[[#This Row],[Salary]]) -> 91846 | F13: =IF(Cleaned_Data4[[#This Row],[Date of Joining]]="","Un-known",Cleaned_Data4[[#This Row],[Date of Joining]]) -> 42071 | G13: =IF(Cleaned_Data4[[#This Row],[Performance Rating]]="","N/A",Cleaned_Data4[[#This Row],[Performance Rating]]) -> N/A | H13: =IF(Cleaned_Data4[[#This Row],[Gender]]="","Un-known",Cleaned_Data4[[#This Row],[Gender]]) -> Male | I13: =IF(Cleaned_Data4[[#This Row],[Email]]="","invalid_email",Cleaned_Data4[[#This Row],[Email]]) -> user153@example.com | K13: IT | L13: =COUNTIF('Raw data for day3'!$C$4:$C$153,K13) -> 25 | O13: SUM() was used to aggregate the total no.of employees in each department. | U13: Email | V13: Not Imputed bcz it has no blank cell.
A14: =Cleaned_Data4[[#This Row],[Employee ID]] -> EMP1010 | B14: =IF(Cleaned_Data4[[#This Row],[Names]]="","Un-known",Cleaned_Data4[[#This Row],[Names]]) -> Sam Wilson | C14: =IF(Cleaned_Data4[[#This Row],[Department]]="","Un-known",Cleaned_Data4[[#This Row],[Department]]) -> Finance | D14: =IF(Cleaned_Data4[[#This Row],[Country]]="","Un-known",Cleaned_Data4[[#This Row],[Country]]) -> UK | E14: =IF(Cleaned_Data4[[#This Row],[Salary]]="N/A","0",Cleaned_Data4[[#This Row],[Salary]]) -> 64247 | F14: =IF(Cleaned_Data4[[#This Row],[Date of Joining]]="","Un-known",Cleaned_Data4[[#This Row],[Date of Joining]]) -> 42078 | G14: =IF(Cleaned_Data4[[#This Row],[Performance Rating]]="","N/A",Cleaned_Data4[[#This Row],[Performance Rating]]) -> 1 | H14: =IF(Cleaned_Data4[[#This Row],[Gender]]="","Un-known",Cleaned_Data4[[#This Row],[Gender]]) -> Female | I14: =IF(Cleaned_Data4[[#This Row],[Email]]="","invalid_email",Cleaned_Data4[[#This Row],[Email]]) -> user18@example.com | K14: Marketing | L14: =COUNTIF('Raw data for day3'!$C$4:$C$153,K14) -> 29 | U14: Employee Id
A15: =Cleaned_Data4[[#This Row],[Employee ID]] -> EMP1011 | B15: =IF(Cleaned_Data4[[#This Row],[Names]]="","Un-known",Cleaned_Data4[[#This Row],[Names]]) -> Sam Wilson | C15: =IF(Cleaned_Data4[[#This Row],[Department]]="","Un-known",Cleaned_Data4[[#This Row],[Department]]) -> IT | D15: =IF(Cleaned_Data4[[#This Row],[Country]]="","Un-known",Cleaned_Data4[[#This Row],[Country]]) -> USA | E15: =IF(Cleaned_Data4[[#This Row],[Salary]]="N/A","0",Cleaned_Data4[[#This Row],[Salary]]) -> 91180 | F15: =IF(Cleaned_Data4[[#This Row],[Date of Joining]]="","Un-known",Cleaned_Data4[[#This Row],[Date of Joining]]) -> 42085 | G15: =IF(Cleaned_Data4[[#This Row],[Performance Rating]]="","N/A",Cleaned_Data4[[#This Row],[Performance Rating]]) -> 5 | H15: =IF(Cleaned_Data4[[#This Row],[Gender]]="","Un-known",Cleaned_Data4[[#This Row],[Gender]]) -> Male | I15: =IF(Cleaned_Data4[[#This Row],[Email]]="","invalid_email",Cleaned_Data4[[#This Row],[Email]]) -> user1@example.com | L15: =COUNTIF('Raw data for day3'!$C$4:$C$153,K15) -> 24
A16: =Cleaned_Data4[[#This Row],[Employee ID]] -> EMP1012 | B16: =IF(Cleaned_Data4[[#This Row],[Names]]="","Un-known",Cleaned_Data4[[#This Row],[Names]]) -> Bob Johnson | C16: =IF(Cleaned_Data4[[#This Row],[Department]]="","Un-known",Cleaned_Data4[[#This Row],[Department]]) -> Sales | D16: =IF(Cleaned_Data4[[#This Row],[Country]]="","Un-known",Cleaned_Data4[[#This Row],[Country]]) -> Un-known | E16: =IF(Cleaned_Data4[[#This Row],[Salary]]="N/A","0",Cleaned_Data4[[#This Row],[Salary]]) -> 96418 | F16: =IF(Cleaned_Data4[[#This Row],[Date of Joining]]="","Un-known",Cleaned_Data4[[#This Row],[Date of Joining]]) -> 42092 | G16: =IF(Cleaned_Data4[[#This Row],[Performance Rating]]="","N/A",Cleaned_Data4[[#This Row],[Performance Rating]]) -> 5 | H16: =IF(Cleaned_Data4[[#This Row],[Gender]]="","Un-known",Cleaned_Data4[[#This Row],[Gender]]) -> Male | I16: =IF(Cleaned_Data4[[#This Row],[Email]]="","invalid_email",Cleaned_Data4[[#This Row],[Email]]) -> user106@example.com | K16: Total | L16: =SUM(L10:M15) -> 150
A17: =Cleaned_Data4[[#This Row],[Employee ID]] -> EMP1013 | B17: =IF(Cleaned_Data4[[#This Row],[Names]]="","Un-known",Cleaned_Data4[[#This Row],[Names]]) -> Sam Wilson | C17: =IF(Cleaned_Data4[[#This Row],[Department]]="","Un-known",Cleaned_Data4[[#This Row],[Department]]) -> Un-known | D17: =IF(Cleaned_Data4[[#This Row],[Country]]="","Un-known",Cleaned_Data4[[#This Row],[Country]]) -> India | E17: =IF(Cleaned_Data4[[#This Row],[Salary]]="N/A","0",Cleaned_Data4[[#This Row],[Salary]]) -> 62158 | F17: =IF(Cleaned_Data4[[#This Row],[Date of Joining]]="","Un-known",Cleaned_Data4[[#This Row],[Date of Joining]]) -> 42099 | G17: =IF(Cleaned_Data4[[#This Row],[Performance Rating]]="","N/A",Cleaned_Data4[[#This Row],[Performance Rating]]) -> 4 | H17: =IF(Cleaned_Data4[[#This Row],[Gender]]="","Un-known",Cleaned_Data4[[#This Row],[Gender]]) -> Un-known | I17: =IF(Cleaned_Data4[[#This Row],[Email]]="","invalid_email",Cleaned_Data4[[#This Row],[Email]]) -> user180@example.com
A18: =Cleaned_Data4[[#This Row],[Employee ID]] -> EMP1014 | B18: =IF(Cleaned_Data4[[#This Row],[Names]]="","Un-known",Cleaned_Data4[[#This Row],[Names]]) -> Jane Smith | C18: =IF(Cleaned_Data4[[#This Row],[Department]]="","Un-known",Cleaned_Data4[[#This Row],[Department]]) -> HR | D18: =IF(Cleaned_Data4[[#This Row],[Country]]="","Un-known",Cleaned_Data4[[#This Row],[Country]]) -> Un-known | E18: =IF(Cleaned_Data4[[#This Row],[Salary]]="N/A","0",Cleaned_Data4[[#This Row],[Salary]]) -> 59894 | F18: =IF(Cleaned_Data4[[#This Row],[Date of Joining]]="","Un-known",Cleaned_Data4[[#This Row],[Date of Joining]]) -> 42106 | G18: =IF(Cleaned_Data4[[#This Row],[Performance Rating]]="","N/A",Cleaned_Data4[[#This Row],[Performance Rating]]) -> 2 | H18: =IF(Cleaned_Data4[[#This Row],[Gender]]="","Un-known",Cleaned_Data4[[#This Row],[Gender]]) -> Male | I18: =IF(Cleaned_Data4[[#This Row],[Email]]="","invalid_email",Cleaned_Data4[[#This Row],[Email]]) -> user184@example.com
A19: =Cleaned_Data4[[#This Row],[Employee ID]] -> EMP1015 | B19: =IF(Cleaned_Data4[[#This Row],[Names]]="","Un-known",Cleaned_Data4[[#This Row],[Names]]) -> Un-known | C19: =IF(Cleaned_Data4[[#This Row],[Department]]="","Un-known",Cleaned_Data4[[#This Row],[Department]]) -> IT | D19: =IF(Cleaned_Data4[[#This Row],[Country]]="","Un-known",Cleaned_Data4[[#This Row],[Country]]) -> India | E19: =IF(Cleaned_Data4[[#This Row],[Salary]]="N/A","0",Cleaned_Data4[[#This Row],[Salary]]) -> 92443 | F19: =IF(Cleaned_Data4[[#This Row],[Date of Joining]]="","Un-known",Cleaned_Data4[[#This Row],[Date of Joining]]) -> 42113 | G19: =IF(Cleaned_Data4[[#This Row],[Performance Rating]]="","N/A",Cleaned_Data4[[#This Row],[Performance Rating]]) -> 3 | H19: =IF(Cleaned_Data4[[#This Row],[Gender]]="","Un-known",Cleaned_Data4[[#This Row],[Gender]]) -> Other | I19: =IF(Cleaned_Data4[[#This Row],[Email]]="","invalid_email",Cleaned_Data4[[#This Row],[Email]]) -> user3@example.com | K19: Unique values in COUNTRY column
A20: =Cleaned_Data4[[#This Row],[Employee ID]] -> EMP1016 | B20: =IF(Cleaned_Data4[[#This Row],[Names]]="","Un-known",Cleaned_Data4[[#This Row],[Names]]) -> Bob Johnson | C20: =IF(Cleaned_Data4[[#This Row],[Department]]="","Un-known",Cleaned_Data4[[#This Row],[Department]]) -> Un-known | D20: =IF(Cleaned_Data4[[#This Row],[Country]]="","Un-known",Cleaned_Data4[[#This Row],[Country]]) -> Germany | E20: =IF(Cleaned_Data4[[#This Row],[Salary]]="N/A","0",Cleaned_Data4[[#This Row],[Salary]]) -> 90271 | F20: =IF(Cleaned_Data4[[#This Row],[Date of Joining]]="","Un-known",Cleaned_Data4[[#This Row],[Date of Joining]]) -> 42120 | G20: =IF(Cleaned_Data4[[#This Row],[Performance Rating]]="","N/A",Cleaned_Data4[[#This Row],[Performance Rating]]) -> N/A | H20: =IF(Cleaned_Data4[[#This Row],[Gender]]="","Un-known",Cleaned_Data4[[#This Row],[Gender]]) -> Un-known | I20: =IF(Cleaned_Data4[[#This Row],[Email]]="","invalid_email",Cleaned_Data4[[#This Row],[Email]]) -> user64@example.com
A21: =Cleaned_Data4[[#This Row],[Employee ID]] -> EMP1017 | B21: =IF(Cleaned_Data4[[#This Row],[Names]]="","Un-known",Cleaned_Data4[[#This Row],[Names]]) -> Jane Smith | C21: =IF(Cleaned_Data4[[#This Row],[Department]]="","Un-known",Cleaned_Data4[[#This Row],[Department]]) -> Finance | D21: =IF(Cleaned_Data4[[#This Row],[Country]]="","Un-known",Cleaned_Data4[[#This Row],[Country]]) -> Australia | E21: =IF(Cleaned_Data4[[#This Row],[Salary]]="N/A","0",Cleaned_Data4[[#This Row],[Salary]]) -> 41341 | F21: =IF(Cleaned_Data4[[#This Row],[Date of Joining]]="","Un-known",Cleaned_Data4[[#This Row],[Date of Joining]]) -> 42127 | G21: =IF(Cleaned_Data4[[#This Row],[Performance Rating]]="","N/A",Cleaned_Data4[[#This Row],[Performance Rating]]) -> 1 | H21: =IF(Cleaned_Data4[[#This Row],[Gender]]="","Un-known",Cleaned_Data4[[#This Row],[Gender]]) -> Other | I21: =IF(Cleaned_Data4[[#This Row],[Email]]="","invalid_email",Cleaned_Data4[[#This Row],[Email]]) -> user38@example.com | K21: Country | L21: No. of Employee from Each country
A22: =Cleaned_Data4[[#This Row],[Employee ID]] -> EMP1018 | B22: =IF(Cleaned_Data4[[#This Row],[Names]]="","Un-known",Cleaned_Data4[[#This Row],[Names]]) -> Alice Brown | C22: =IF(Cleaned_Data4[[#This Row],[Department]]="","Un-known",Cleaned_Data4[[#This Row],[Department]]) -> Finance | D22: =IF(Cleaned_Data4[[#This Row],[Country]]="","Un-known",Cleaned_Data4[[#This Row],[Country]]) -> UK | E22: =IF(Cleaned_Data4[[#This Row],[Salary]]="N/A","0",Cleaned_Data4[[#This Row],[Salary]]) -> 73602 | F22: =IF(Cleaned_Data4[[#This Row],[Date of Joining]]="","Un-known",Cleaned_Data4[[#This Row],[Date of Joining]]) -> 42134 | G22: =IF(Cleaned_Data4[[#This Row],[Performance Rating]]="","N/A",Cleaned_Data4[[#This Row],[Performance Rating]]) -> N/A | H22: =IF(Cleaned_Data4[[#This Row],[Gender]]="","Un-known",Cleaned_Data4[[#This Row],[Gender]]) -> Un-known | I22: =IF(Cleaned_Data4[[#This Row],[Email]]="","invalid_email",Cleaned_Data4[[#This Row],[Email]]) -> user96@example.com
A23: =Cleaned_Data4[[#This Row],[Employee ID]] -> EMP1019 | B23: =IF(Cleaned_Data4[[#This Row],[Names]]="","Un-known",Cleaned_Data4[[#This Row],[Names]]) -> Eve Adams | C23: =IF(Cleaned_Data4[[#This Row],[Department]]="","Un-known",Cleaned_Data4[[#This Row],[Department]]) -> Un-known | D23: =IF(Cleaned_Data4[[#This Row],[Country]]="","Un-known",Cleaned_Data4[[#This Row],[Country]]) -> India | E23: =IF(Cleaned_Data4[[#This Row],[Salary]]="N/A","0",Cleaned_Data4[[#This Row],[Salary]]) -> 67531 | F23: =IF(Cleaned_Data4[[#This Row],[Date of Joining]]="","Un-known",Cleaned_Data4[[#This Row],[Date of Joining]]) -> 42141 | G23: =IF(Cleaned_Data4[[#This Row],[Performance Rating]]="","N/A",Cleaned_Data4[[#This Row],[Performance Rating]]) -> 5 | H23: =IF(Cleaned_Data4[[#This Row],[Gender]]="","Un-known",Cleaned_Data4[[#This Row],[Gender]]) -> Female | I23: =IF(Cleaned_Data4[[#This Row],[Email]]="","invalid_email",Cleaned_Data4[[#This Row],[Email]]) -> user151@example.com | K23: {=_xlfn.UNIQUE(Cleaned_Data4[Country])} | L23: =COUNTIF('Raw data for day3'!$D$4:$D$153,K23) -> 31 | O23: UNIQUE() used to list the distinct values in Country column.
A24: =Cleaned_Data4[[#This Row],[Employee ID]] -> EMP1020 | B24: =IF(Cleaned_Data4[[#This Row],[Names]]="","Un-known",Cleaned_Data4[[#This Row],[Names]]) -> Jane Smith | C24: =IF(Cleaned_Data4[[#This Row],[Department]]="","Un-known",Cleaned_Data4[[#This Row],[Department]]) -> HR | D24: =IF(Cleaned_Data4[[#This Row],[Country]]="","Un-known",Cleaned_Data4[[#This Row],[Country]]) -> USA | E24: =IF(Cleaned_Data4[[#This Row],[Salary]]="N/A","0",Cleaned_Data4[[#This Row],[Salary]]) -> 0 | F24: =IF(Cleaned_Data4[[#This Row],[Date of Joining]]="","Un-known",Cleaned_Data4[[#This Row],[Date of Joining]]) -> 42148 | G24: =IF(Cleaned_Data4[[#This Row],[Performance Rating]]="","N/A",Cleaned_Data4[[#This Row],[Performance Rating]]) -> 2 | H24: =IF(Cleaned_Data4[[#This Row],[Gender]]="","Un-known",Cleaned_Data4[[#This Row],[Gender]]) -> Other | I24: =IF(Cleaned_Data4[[#This Row],[Email]]="","invalid_email",Cleaned_Data4[[#This Row],[Email]]) -> user200@example.com | K24: Germany | L24: =COUNTIF('Raw data for day3'!$D$4:$D$153,K24) -> 23 | O24: COUNTIF() applied to determine the total No. of Employees in each country.
A25: =Cleaned_Data4[[#This Row],[Employee ID]] -> EMP1021 | B25: =IF(Cleaned_Data4[[#This Row],[Names]]="","Un-known",Cleaned_Data4[[#This Row],[Names]]) -> Jane Smith | C25: =IF(Cleaned_Data4[[#This Row],[Department]]="","Un-known",Cleaned_Data4[[#This Row],[Department]]) -> HR | D25: =IF(Cleaned_Data4[[#This Row],[Country]]="","Un-known",Cleaned_Data4[[#This Row],[Country]]) -> Un-known | E25: =IF(Cleaned_Data4[[#This Row],[Salary]]="N/A","0",Cleaned_Data4[[#This Row],[Salary]]) -> 98922 | F25: =IF(Cleaned_Data4[[#This Row],[Date of Joining]]="","Un-known",Cleaned_Data4[[#This Row],[Date of Joining]]) -> 42155 | G25: =IF(Cleaned_Data4[[#This Row],[Performance Rating]]="","N/A",Cleaned_Data4[[#This Row],[Performance Rating]]) -> 4 | H25: =IF(Cleaned_Data4[[#This Row],[Gender]]="","Un-known",Cleaned_Data4[[#This Row],[Gender]]) -> Un-known | I25: =IF(Cleaned_Data4[[#This Row],[Email]]="","invalid_email",Cleaned_Data4[[#This Row],[Email]]) -> user77@example.com | K25: USA | L25: =COUNTIF('Raw data for day3'!$D$4:$D$153,K25) -> 24
A26: =Cleaned_Data4[[#This Row],[Employee ID]] -> EMP1022 | B26: =IF(Cleaned_Data4[[#This Row],[Names]]="","Un-known",Cleaned_Data4[[#This Row],[Names]]) -> Eve Adams | C26: =IF(Cleaned_Data4[[#This Row],[Department]]="","Un-known",Cleaned_Data4[[#This Row],[Department]]) -> Finance | D26: =IF(Cleaned_Data4[[#This Row],[Country]]="","Un-known",Cleaned_Data4[[#This Row],[Country]]) -> India | E26: =IF(Cleaned_Data4[[#This Row],[Salary]]="N/A","0",Cleaned_Data4[[#This Row],[Salary]]) -> 38333 | F26: =IF(Cleaned_Data4[[#This Row],[Date of Joining]]="","Un-known",Cleaned_Data4[[#This Row],[Date of Joining]]) -> 42162 | G26: =IF(Cleaned_Data4[[#This Row],[Performance Rating]]="","N/A",Cleaned_Data4[[#This Row],[Performance Rating]]) -> 5 | H26: =IF(Cleaned_Data4[[#This Row],[Gender]]="","Un-known",Cleaned_Data4[[#This Row],[Gender]]) -> Un-known | I26: =IF(Cleaned_Data4[[#This Row],[Email]]="","invalid_email",Cleaned_Data4[[#This Row],[Email]]) -> user128@example.com | K26: India | L26: =COUNTIF('Raw data for day3'!$D$4:$D$153,K26) -> 28 | O26: SUM() applied to determine the overall employee count for all Country.
A27: =Cleaned_Data4[[#This Row],[Employee ID]] -> EMP1023 | B27: =IF(Cleaned_Data4[[#This Row],[Names]]="","Un-known",Cleaned_Data4[[#This Row],[Names]]) -> Alice Brown | C27: =IF(Cleaned_Data4[[#This Row],[Department]]="","Un-known",Cleaned_Data4[[#This Row],[Department]]) -> Marketing | D27: =IF(Cleaned_Data4[[#This Row],[Country]]="","Un-known",Cleaned_Data4[[#This Row],[Country]]) -> UK | E27: =IF(Cleaned_Data4[[#This Row],[Salary]]="N/A","0",Cleaned_Data4[[#This Row],[Salary]]) -> 36515 | F27: =IF(Cleaned_Data4[[#This Row],[Date of Joining]]="","Un-known",Cleaned_Data4[[#This Row],[Date of Joining]]) -> 42169 | G27: =IF(Cleaned_Data4[[#This Row],[Performance Rating]]="","N/A",Cleaned_Data4[[#This Row],[Performance Rating]]) -> 3 | H27: =IF(Cleaned_Data4[[#This Row],[Gender]]="","Un-known",Cleaned_Data4[[#This Row],[Gender]]) -> Male | I27: =IF(Cleaned_Data4[[#This Row],[Email]]="","invalid_email",Cleaned_Data4[[#This Row],[Email]]) -> user149@example.com | K27: UK | L27: =COUNTIF('Raw data for day3'!$D$4:$D$153,K27) -> 25
A28: =Cleaned_Data4[[#This Row],[Employee ID]] -> EMP1024 | B28: =IF(Cleaned_Data4[[#This Row],[Names]]="","Un-known",Cleaned_Data4[[#This Row],[Names]]) -> Sam Wilson | C28: =IF(Cleaned_Data4[[#This Row],[Department]]="","Un-known",Cleaned_Data4[[#This Row],[Department]]) -> Finance | D28: =IF(Cleaned_Data4[[#This Row],[Country]]="","Un-known",Cleaned_Data4[[#This Row],[Country]]) -> Un-known | E28: =IF(Cleaned_Data4[[#This Row],[Salary]]="N/A","0",Cleaned_Data4[[#This Row],[Salary]]) -> 91005 | F28: =IF(Cleaned_Data4[[#This Row],[Date of Joining]]="","Un-known",Cleaned_Data4[[#This Row],[Date of Joining]]) -> 42176 | G28: =IF(Cleaned_Data4[[#This Row],[Performance Rating]]="","N/A",Cleaned_Data4[[#This Row],[Performance Rating]]) -> 1 | H28: =IF(Cleaned_Data4[[#This Row],[Gender]]="","Un-known",Cleaned_Data4[[#This Row],[Gender]]) -> Other | I28: =IF(Cleaned_Data4[[#This Row],[Email]]="","invalid_email",Cleaned_Data4[[#This Row],[Email]]) -> user122@example.com | K28: Australia | L28: =COUNTIF('Raw data for day3'!$D$4:$D$153,K28) -> 19
A29: =Cleaned_Data4[[#This Row],[Employee ID]] -> EMP1025 | B29: =IF(Cleaned_Data4[[#This Row],[Names]]="","Un-known",Cleaned_Data4[[#This Row],[Names]]) -> Chris Lee | C29: =IF(Cleaned_Data4[[#This Row],[Department]]="","Un-known",Cleaned_Data4[[#This Row],[Department]]) -> Un-known | D29: =IF(Cleaned_Data4[[#This Row],[Country]]="","Un-known",Cleaned_Data4[[#This Row],[Country]]) -> Un-known | E29: =IF(Cleaned_Data4[[#This Row],[Salary]]="N/A","0",Cleaned_Data4[[#This Row],[Salary]]) -> 52272 | F29: =IF(Cleaned_Data4[[#This Row],[Date of Joining]]="","Un-known",Cleaned_Data4[[#This Row],[Date of Joining]]) -> 42183 | G29: =IF(Cleaned_Data4[[#This Row],[Performance Rating]]="","N/A",Cleaned_Data4[[#This Row],[Performance Rating]]) -> 3 | H29: =IF(Cleaned_Data4[[#This Row],[Gender]]="","Un-known",Cleaned_Data4[[#This Row],[Gender]]) -> Un-known | I29: =IF(Cleaned_Data4[[#This Row],[Email]]="","invalid_email",Cleaned_Data4[[#This Row],[Email]]) -> user41@example.com | K29: Total | L29: =SUM(L23:M28) -> 150
A30: =Cleaned_Data4[[#This Row],[Employee ID]] -> EMP1026 | B30: =IF(Cleaned_Data4[[#This Row],[Names]]="","Un-known",Cleaned_Data4[[#This Row],[Names]]) -> Eve Adams | C30: =IF(Cleaned_Data4[[#This Row],[Department]]="","Un-known",Cleaned_Data4[[#This Row],[Department]]) -> Sales | D30: =IF(Cleaned_Data4[[#This Row],[Country]]="","Un-known",Cleaned_Data4[[#This Row],[Country]]) -> Germany | E30: =IF(Cleaned_Data4[[#This Row],[Salary]]="N/A","0",Cleaned_Data4[[#This Row],[Salary]]) -> 76518 | F30: =IF(Cleaned_Data4[[#This Row],[Date of Joining]]="","Un-known",Cleaned_Data4[[#This Row],[Date of Joining]]) -> 42190 | G30: =IF(Cleaned_Data4[[#This Row],[Performance Rating]]="","N/A",Cleaned_Data4[[#This Row],[Performance Rating]]) -> 2 | H30: =IF(Cleaned_Data4[[#This Row],[Gender]]="","Un-known",Cleaned_Data4[[#This Row],[Gender]]) -> Female | I30: =IF(Cleaned_Data4[[#This Row],[Email]]="","invalid_email",Cleaned_Data4[[#This Row],[Email]]) -> user68@example.com
A31: =Cleaned_Data4[[#This Row],[Employee ID]] -> EMP1027 | B31: =IF(Cleaned_Data4[[#This Row],[Names]]="","Un-known",Cleaned_Data4[[#This Row],[Names]]) -> Alice Brown | C31: =IF(Cleaned_Data4[[#This Row],[Department]]="","Un-known",Cleaned_Data4[[#This Row],[Department]]) -> IT | D31: =IF(Cleaned_Data4[[#This Row],[Country]]="","Un-known",Cleaned_Data4[[#This Row],[Country]]) -> UK | E31: =IF(Cleaned_Data4[[#This Row],[Salary]]="N/A","0",Cleaned_Data4[[#This Row],[Salary]]) -> 41448 | F31: =IF(Cleaned_Data4[[#This Row],[Date of Joining]]="","Un-known",Cleaned_Data4[[#This Row],[Date of Joining]]) -> 42197 | G31: =IF(Cleaned_Data4[[#This Row],[Performance Rating]]="","N/A",Cleaned_Data4[[#This Row],[Performance Rating]]) -> 3 | H31: =IF(Cleaned_Data4[[#This Row],[Gender]]="","Un-known",Cleaned_Data4[[#This Row],[Gender]]) -> Other | I31: =IF(Cleaned_Data4[[#This Row],[Email]]="","invalid_email",Cleaned_Data4[[#This Row],[Email]]) -> user103@example.com
A32: =Cleaned_Data4[[#This Row],[Employee ID]] -> EMP1028 | B32: =IF(Cleaned_Data4[[#This Row],[Names]]="","Un-known",Cleaned_Data4[[#This Row],[Names]]) -> John Doe | C32: =IF(Cleaned_Data4[[#This Row],[Department]]="","Un-known",Cleaned_Data4[[#This Row],[Department]]) -> HR | D32: =IF(Cleaned_Data4[[#This Row],[Country]]="","Un-known",Cleaned_Data4[[#This Row],[Country]]) -> UK | E32: =IF(Cleaned_Data4[[#This Row],[Salary]]="N/A","0",Cleaned_Data4[[#This Row],[Salary]]) -> 49282 | F32: =IF(Cleaned_Data4[[#This Row],[Date of Joining]]="","Un-known",Cleaned_Data4[[#This Row],[Date of Joining]]) -> 42204 | G32: =IF(Cleaned_Data4[[#This Row],[Performance Rating]]="","N/A",Cleaned_Data4[[#This Row],[Performance Rating]]) -> 2 | H32: =IF(Cleaned_Data4[[#This Row],[Gender]]="","Un-known",Cleaned_Data4[[#This Row],[Gender]]) -> Female | I32: =IF(Cleaned_Data4[[#This Row],[Email]]="","invalid_email",Cleaned_Data4[[#This Row],[Email]]) -> user135@example.com | K32: Unique values in PERFORMANCE RATING column
A33: =Cleaned_Data4[[#This Row],[Employee ID]] -> EMP1029 | B33: =IF(Cleaned_Data4[[#This Row],[Names]]="","Un-known",Cleaned_Data4[[#This Row],[Names]]) -> Bob Johnson | C33: =IF(Cleaned_Data4[[#This Row],[Department]]="","Un-known",Cleaned_Data4[[#This Row],[Department]]) -> Marketing | D33: =IF(Cleaned_Data4[[#This Row],[Country]]="","Un-known",Cleaned_Data4[[#This Row],[Country]]) -> UK | E33: =IF(Cleaned_Data4[[#This Row],[Salary]]="N/A","0",Cleaned_Data4[[#This Row],[Salary]]) -> 92959 | F33: =IF(Cleaned_Data4[[#This Row],[Date of Joining]]="","Un-known",Cleaned_Data4[[#This Row],[Date of Joining]]) -> 42211 | G33: =IF(Cleaned_Data4[[#This Row],[Performance Rating]]="","N/A",Cleaned_Data4[[#This Row],[Performance Rating]]) -> 5 | H33: =IF(Cleaned_Data4[[#This Row],[Gender]]="","Un-known",Cleaned_Data4[[#This Row],[Gender]]) -> Un-known | I33: =IF(Cleaned_Data4[[#This Row],[Email]]="","invalid_email",Cleaned_Data4[[#This Row],[Email]]) -> user83@example.com
A34: =Cleaned_Data4[[#This Row],[Employee ID]] -> EMP1030 | B34: =IF(Cleaned_Data4[[#This Row],[Names]]="","Un-known",Cleaned_Data4[[#This Row],[Names]]) -> Un-known | C34: =IF(Cleaned_Data4[[#This Row],[Department]]="","Un-known",Cleaned_Data4[[#This Row],[Department]]) -> Marketing | D34: =IF(Cleaned_Data4[[#This Row],[Country]]="","Un-known",Cleaned_Data4[[#This Row],[Country]]) -> Un-known | E34: =IF(Cleaned_Data4[[#This Row],[Salary]]="N/A","0",Cleaned_Data4[[#This Row],[Salary]]) -> 92259 | F34: =IF(Cleaned_Data4[[#This Row],[Date of Joining]]="","Un-known",Cleaned_Data4[[#This Row],[Date of Joining]]) -> Un-known | G34: =IF(Cleaned_Data4[[#This Row],[Performance Rating]]="","N/A",Cleaned_Data4[[#This Row],[Performance Rating]]) -> 1 | H34: =IF(Cleaned_Data4[[#This Row],[Gender]]="","Un-known",Cleaned_Data4[[#This Row],[Gender]]) -> Unknown | I34: =IF(Cleaned_Data4[[#This Row],[Email]]="","invalid_email",Cleaned_Data4[[#This Row],[Email]]) -> user109@example.com | K34: Performance Rating | L34: Count of Performance Rating
A35: =Cleaned_Data4[[#This Row],[Employee ID]] -> EMP1031 | B35: =IF(Cleaned_Data4[[#This Row],[Names]]="","Un-known",Cleaned_Data4[[#This Row],[Names]]) -> Eve Adams | C35: =IF(Cleaned_Data4[[#This Row],[Department]]="","Un-known",Cleaned_Data4[[#This Row],[Department]]) -> HR | D35: =IF(Cleaned_Data4[[#This Row],[Country]]="","Un-known",Cleaned_Data4[[#This Row],[Country]]) -> Germany | E35: =IF(Cleaned_Data4[[#This Row],[Salary]]="N/A","0",Cleaned_Data4[[#This Row],[Salary]]) -> 92299 | F35: =IF(Cleaned_Data4[[#This Row],[Date of Joining]]="","Un-known",Cleaned_Data4[[#This Row],[Date of Joining]]) -> 42225 | G35: =IF(Cleaned_Data4[[#This Row],[Performance Rating]]="","N/A",Cleaned_Data4[[#This Row],[Performance Rating]]) -> 3 | H35: =IF(Cleaned_Data4[[#This Row],[Gender]]="","Un-known",Cleaned_Data4[[#This Row],[Gender]]) -> Male | I35: =IF(Cleaned_Data4[[#This Row],[Email]]="","invalid_email",Cleaned_Data4[[#This Row],[Email]]) -> user143@example.com
A36: =Cleaned_Data4[[#This Row],[Employee ID]] -> EMP1032 | B36: =IF(Cleaned_Data4[[#This Row],[Names]]="","Un-known",Cleaned_Data4[[#This Row],[Names]]) -> Sam Wilson | C36: =IF(Cleaned_Data4[[#This Row],[Department]]="","Un-known",Cleaned_Data4[[#This Row],[Department]]) -> HR | D36: =IF(Cleaned_Data4[[#This Row],[Country]]="","Un-known",Cleaned_Data4[[#This Row],[Country]]) -> Un-known | E36: =IF(Cleaned_Data4[[#This Row],[Salary]]="N/A","0",Cleaned_Data4[[#This Row],[Salary]]) -> 95586 | F36: =IF(Cleaned_Data4[[#This Row],[Date of Joining]]="","Un-known",Cleaned_Data4[[#This Row],[Date of Joining]]) -> 42232 | G36: =IF(Cleaned_Data4[[#This Row],[Performance Rating]]="","N/A",Cleaned_Data4[[#This Row],[Performance Rating]]) -> 3 | H36: =IF(Cleaned_Data4[[#This Row],[Gender]]="","Un-known",Cleaned_Data4[[#This Row],[Gender]]) -> Other | I36: =IF(Cleaned_Data4[[#This Row],[Email]]="","invalid_email",Cleaned_Data4[[#This Row],[Email]]) -> user190@example.com | K36: {=_xlfn.UNIQUE(Cleaned_Data4[Performance Rating])} -> 2 | L36: =COUNTIF('Raw data for day3'!$H$4:$H$153,K36) -> 23 | O36: Different performance rating scales were identified using the UNIQUE() function.
A37: =Cleaned_Data4[[#This Row],[Employee ID]] -> EMP1033 | B37: =IF(Cleaned_Data4[[#This Row],[Names]]="","Un-known",Cleaned_Data4[[#This Row],[Names]]) -> Chris Lee | C37: =IF(Cleaned_Data4[[#This Row],[Department]]="","Un-known",Cleaned_Data4[[#This Row],[Department]]) -> Un-known | D37: =IF(Cleaned_Data4[[#This Row],[Country]]="","Un-known",Cleaned_Data4[[#This Row],[Country]]) -> USA | E37: =IF(Cleaned_Data4[[#This Row],[Salary]]="N/A","0",Cleaned_Data4[[#This Row],[Salary]]) -> 95367 | F37: =IF(Cleaned_Data4[[#This Row],[Date of Joining]]="","Un-known",Cleaned_Data4[[#This Row],[Date of Joining]]) -> 42239 | G37: =IF(Cleaned_Data4[[#This Row],[Performance Rating]]="","N/A",Cleaned_Data4[[#This Row],[Performance Rating]]) -> N/A | H37: =IF(Cleaned_Data4[[#This Row],[Gender]]="","Un-known",Cleaned_Data4[[#This Row],[Gender]]) -> Male | I37: =IF(Cleaned_Data4[[#This Row],[Email]]="","invalid_email",Cleaned_Data4[[#This Row],[Email]]) -> user136@example.com | K37: 1 | L37: =COUNTIF('Raw data for day3'!$H$4:$H$153,K37) -> 30
A38: =Cleaned_Data4[[#This Row],[Employee ID]] -> EMP1034 | B38: =IF(Cleaned_Data4[[#This Row],[Names]]="","Un-known",Cleaned_Data4[[#This Row],[Names]]) -> John Doe | C38: =IF(Cleaned_Data4[[#This Row],[Department]]="","Un-known",Cleaned_Data4[[#This Row],[Department]]) -> Sales | D38: =IF(Cleaned_Data4[[#This Row],[Country]]="","Un-known",Cleaned_Data4[[#This Row],[Country]]) -> Australia | E38: =IF(Cleaned_Data4[[#This Row],[Salary]]="N/A","0",Cleaned_Data4[[#This Row],[Salary]]) -> 79549 | F38: =IF(Cleaned_Data4[[#This Row],[Date of Joining]]="","Un-known",Cleaned_Data4[[#This Row],[Date of Joining]]) -> 42246 | G38: =IF(Cleaned_Data4[[#This Row],[Performance Rating]]="","N/A",Cleaned_Data4[[#This Row],[Performance Rating]]) -> 3 | H38: =IF(Cleaned_Data4[[#This Row],[Gender]]="","Un-known",Cleaned_Data4[[#This Row],[Gender]]) -> Un-known | I38: =IF(Cleaned_Data4[[#This Row],[Email]]="","invalid_email",Cleaned_Data4[[#This Row],[Email]]) -> user198@example.com | L38: =COUNTIF('Raw data for day3'!$H$4:$H$153,K38) -> 25 | O38: COUNTIF() applied to calculate the employees count for each scale.
A39: =Cleaned_Data4[[#This Row],[Employee ID]] -> EMP1035 | B39: =IF(Cleaned_Data4[[#This Row],[Names]]="","Un-known",Cleaned_Data4[[#This Row],[Names]]) -> Alice Brown | C39: =IF(Cleaned_Data4[[#This Row],[Department]]="","Un-known",Cleaned_Data4[[#This Row],[Department]]) -> Un-known | D39: =IF(Cleaned_Data4[[#This Row],[Country]]="","Un-known",Cleaned_Data4[[#This Row],[Country]]) -> UK | E39: =IF(Cleaned_Data4[[#This Row],[Salary]]="N/A","0",Cleaned_Data4[[#This Row],[Salary]]) -> 54463 | F39: =IF(Cleaned_Data4[[#This Row],[Date of Joining]]="","Un-known",Cleaned_Data4[[#This Row],[Date of Joining]]) -> 42253 | G39: =IF(Cleaned_Data4[[#This Row],[Performance Rating]]="","N/A",Cleaned_Data4[[#This Row],[Performance Rating]]) -> 4 | H39: =IF(Cleaned_Data4[[#This Row],[Gender]]="","Un-known",Cleaned_Data4[[#This Row],[Gender]]) -> Male | I39: =IF(Cleaned_Data4[[#This Row],[Email]]="","invalid_email",Cleaned_Data4[[#This Row],[Email]]) -> invalid_email | K39: 5 | L39: =COUNTIF('Raw data for day3'!$H$4:$H$153,K39) -> 25
A40: =Cleaned_Data4[[#This Row],[Employee ID]] -> EMP1036 | B40: =IF(Cleaned_Data4[[#This Row],[Names]]="","Un-known",Cleaned_Data4[[#This Row],[Names]]) -> Alice Brown | C40: =IF(Cleaned_Data4[[#This Row],[Department]]="","Un-known",Cleaned_Data4[[#This Row],[Department]]) -> IT | D40: =IF(Cleaned_Data4[[#This Row],[Country]]="","Un-known",Cleaned_Data4[[#This Row],[Country]]) -> USA | E40: =IF(Cleaned_Data4[[#This Row],[Salary]]="N/A","0",Cleaned_Data4[[#This Row],[Salary]]) -> 89781 | F40: =IF(Cleaned_Data4[[#This Row],[Date of Joining]]="","Un-known",Cleaned_Data4[[#This Row],[Date of Joining]]) -> 42260 | G40: =IF(Cleaned_Data4[[#This Row],[Performance Rating]]="","N/A",Cleaned_Data4[[#This Row],[Performance Rating]]) -> N/A | H40: =IF(Cleaned_Data4[[#This Row],[Gender]]="","Un-known",Cleaned_Data4[[#This Row],[Gender]]) -> Female | I40: =IF(Cleaned_Data4[[#This Row],[Email]]="","invalid_email",Cleaned_Data4[[#This Row],[Email]]) -> user31@example.com | K40: 4 | L40: =COUNTIF('Raw data for day3'!$H$4:$H$153,K40) -> 17 | O40: SUM() applied to consolidate performance rating across all employees.
...
