Workbook

Sheet Raw data for Day5
A1: RAW DATA FOR DAY5 CHALLENGE
A2: Employee ID | B2: Names | C2: Department | D2: Country | E2: Salary | F2: Date of Joining | G2: Performance Rating | H2: Gender | I2: Email
A3: EMP1000 | B3: Un-known | C3: finance | D3: Un-known | E3: 0 | F3: Un-known | G3: 2 | H3: Unknown | I3: INVALID_EMAIL
A4: EMP1001 | B4: Eve Adams | C4: hr | D4: germany | E4: 54255 | F4: 42015 | G4: 1 | H4: Other | I4: USER106@example.COM
A5: EMP1002 | B5: Alice Brown | C5: finance | D5: germany | E5: 63184 | F5: 42022 | G5: 2 | H5: Un-known | I5: USER176@example.COM
A6: EMP1003 | B6: John Doe | C6: sales | D6: usa | E6: 94406 | F6: 42029 | G6: 1 | H6: Male | I6: USER168@example.COM
A7: EMP1004 | B7: Jane Smith | C7: sales | D7: germany | E7: 64120 | F7: 42036 | G7: 1 | H7: Male | I7: USER49@example.COM
A8: EMP1005 | B8: Alice Brown | C8: it | D8: india | E8: 78421 | F8: 42043 | G8: 2 | H8: Female | I8: USER24@example.COM
A9: EMP1006 | B9: Sam Wilson | C9: sales | D9: Un-known | E9: 67721 | F9: 42050 | G9: N/A | H9: Male | I9: USER168@example.COM
A10: EMP1007 | B10: Chris Lee | C10: marketing | D10: Un-known | E10: 35364 | F10: 42057 | G10: 2 | H10: Other | I10: USER26@example.COM
A11: EMP1008 | B11: Alice Brown | C11: it | D11: germany | E11: 97881 | F11: 42064 | G11: N/A | H11: Female | I11: USER25@example.COM
A12: EMP1009 | B12: Chris Lee | C12: hr | D12: uk | E12: 91846 | F12: 42071 | G12: N/A | H12: Male | I12: USER153@example.COM
A13: EMP1010 | B13: Sam Wilson | C13: finance | D13: uk | E13: 64247 | F13: 42078 | G13: 1 | H13: Female | I13: USER18@example.COM
A14: EMP1011 | B14: Sam Wilson | C14: it | D14: usa | E14: 91180 | F14: 42085 | G14: 5 | H14: Male | I14: USER1@example.COM
A15: EMP1012 | B15: Bob Johnson | C15: sales | D15: Un-known | E15: 96418 | F15: 42092 | G15: 5 | H15: Male | I15: USER106@example.COM
A16: EMP1013 | B16: Sam Wilson | C16: Un-known | D16: india | E16: 62158 | F16: 42099 | G16: 4 | H16: Un-known | I16: USER180@example.COM
A17: EMP1014 | B17: Jane Smith | C17: hr | D17: Un-known | E17: 59894 | F17: 42106 | G17: 2 | H17: Male | I17: USER184@example.COM
A18: EMP1015 | B18: Un-known | C18: it | D18: india | E18: 92443 | F18: 42113 | G18: 3 | H18: Other | I18: USER3@example.COM
A19: EMP1016 | B19: Bob Johnson | C19: Un-known | D19: germany | E19: 90271 | F19: 42120 | G19: N/A | H19: Un-known | I19: USER64@example.COM
A20: EMP1017 | B20: Jane Smith | C20: finance | D20: Australia | E20: 41341 | F20: 42127 | G20: 1 | H20: Other | I20: USER38@example.COM
A21: EMP1018 | B21: Alice Brown | C21: finance | D21: uk | E21: 73602 | F21: 42134 | G21: N/A | H21: Un-known | I21: USER96@example.COM
A22: EMP1019 | B22: Eve Adams | C22: Un-known | D22: india | E22: 67531 | F22: 42141 | G22: 5 | H22: Female | I22: USER151@example.COM
A23: EMP1020 | B23: Jane Smith | C23: hr | D23: usa | E23: 0 | F23: 42148 | G23: 2 | H23: Other | I23: USER200@example.COM
A24: EMP1021 | B24: Jane Smith | C24: hr | D24: Un-known | E24: 98922 | F24: 42155 | G24: 4 | H24: Un-known | I24: USER77@example.COM
A25: EMP1022 | B25: Eve Adams | C25: finance | D25: india | E25: 38333 | F25: 42162 | G25: 5 | H25: Un-known | I25: USER128@example.COM
A26: EMP1023 | B26: Alice Brown | C26: marketing | D26: uk | E26: 36515 | F26: 42169 | G26: 3 | H26: Male | I26: USER149@example.COM
A27: EMP1024 | B27: Sam Wilson | C27: finance | D27: Un-known | E27: 91005 | F27: 42176 | G27: 1 | H27: Other | I27: USER122@example.COM
A28: EMP1025 | B28: Chris Lee | C28: Un-known | D28: Un-known | E28: 52272 | F28: 42183 | G28: 3 | H28: Un-known | I28: USER41@example.COM
A29: EMP1026 | B29: Eve Adams | C29: sales | D29: germany | E29: 76518 | F29: 42190 | G29: 2 | H29: Female | I29: USER68@example.COM
A30: EMP1027 | B30: Alice Brown | C30: it | D30: uk | E30: 41448 | F30: 42197 | G30: 3 | H30: Other | I30: USER103@example.COM
A31: EMP1028 | B31: John Doe | C31: hr | D31: uk | E31: 49282 | F31: 42204 | G31: 2 | H31: Female | I31: USER135@example.COM
A32: EMP1029 | B32: Bob Johnson | C32: marketing | D32: uk | E32: 92959 | F32: 42211 | G32: 5 | H32: Un-known | I32: USER83@example.COM
A33: EMP1030 | B33: Un-known | C33: marketing | D33: Un-known | E33: 92259 | F33: Un-known | G33: 1 | H33: Unknown | I33: USER109@example.COM
A34: EMP1031 | B34: Eve Adams | C34: hr | D34: germany | E34: 92299 | F34: 42225 | G34: 3 | H34: Male | I34: USER143@example.COM
A35: EMP1032 | B35: Sam Wilson | C35: hr | D35: Un-known | E35: 95586 | F35: 42232 | G35: 3 | H35: Other | I35: USER190@example.COM
A36: EMP1033 | B36: Chris Lee | C36: Un-known | D36: usa | E36: 95367 | F36: 42239 | G36: N/A | H36: Male | I36: USER136@example.COM
A37: EMP1034 | B37: John Doe | C37: sales | D37: Australia | E37: 79549 | F37: 42246 | G37: 3 | H37: Un-known | I37: USER198@example.COM
A38: EMP1035 | B38: Alice Brown | C38: Un-known | D38: uk | E38: 54463 | F38: 42253 | G38: 4 | H38: Male | I38: INVALID_EMAIL
A39: EMP1036 | B39: Alice Brown | C39: it | D39: usa | E39: 89781 | F39: 42260 | G39: N/A | H39: Female | I39: USER31@example.COM
A40: EMP1037 | B40: Alice Brown | C40: hr | D40: Un-known | E40: 64796 | F40: 42267 | G40: N/A | H40: Other | I40: USER98@example.COM
...

Sheet Day5
A1: DAY 5 CHALLENGE - UTILISING TEXT FUNCTIONS
A2: Employee ID | C2: Names | D2: Department | E2: Country | F2: Salary | G2: Date of Joining | H2: Performance Rating | I2: Gender | J2: Email | L2: DESCRIPTION OF THE PROCESS
A3: =CLEAN(TRIM(LEFT('Raw data for Day5'!A3,3))) -> EMP | B3: =CLEAN(TRIM(RIGHT('Raw data for Day5'!A3,4))) -> 1000 | C3: =CLEAN(TRIM(PROPER('Raw data for Day5'!B3))) -> Un-Known | D3: =CLEAN(TRIM(IF('Raw data for Day5'!C3="finance",PROPER('Raw data for Day5'!C3),IF('Raw data for Day5'!C3="hr", UPPER('Raw data for Day5'!C3),IF('Raw data for Day5'!C3="it",UPPER('Raw data for Day5'!C3),IF('Raw data for Day5'!C3="sales",PROPER('Raw data for Day5'!C3),IF('Raw data for Day5'!C3="marketing",PROPER('Raw data for Day5'!C3),"Un-known"))))))) -> Finance | E3: =CLEAN(TRIM(IF('Raw data for Day5'!D3="germany",PROPER('Raw data for Day5'!D3),IF('Raw data for Day5'!D3="usa",UPPER('Raw data for Day5'!D3),IF('Raw data for Day5'!D3="uk",UPPER('Raw data for Day5'!D3),IF('Raw data for Day5'!D3="india",PROPER('Raw data for Day5'!D3),'Raw data for Day5'!D3)))))) -> Un-known | F3: ='Raw data for Day5'!E3 -> 0 | G3: ='Raw data for Day5'!F3 -> Un-known | H3: =CLEAN(TRIM('Raw data for Day5'!G3)) -> 2 | I3: =CLEAN(TRIM('Raw data for Day5'!H3)) -> Unknown | J3: =CLEAN(TRIM(LOWER('Raw data for Day5'!I3))) -> invalid_email | L3: Employee ID | M3: By using LEFT() & RIGHT() Text (EMP) and Numerical value(1000, 1001,..) was extracted from the column Employee ID.
A4: =CLEAN(TRIM(LEFT('Raw data for Day5'!A4,3))) -> EMP | B4: =CLEAN(TRIM(RIGHT('Raw data for Day5'!A4,4))) -> 1001 | C4: =CLEAN(TRIM(PROPER('Raw data for Day5'!B4))) -> Eve Adams | D4: =CLEAN(TRIM(IF('Raw data for Day5'!C4="finance",PROPER('Raw data for Day5'!C4),IF('Raw data for Day5'!C4="hr", UPPER('Raw data for Day5'!C4),IF('Raw data for Day5'!C4="it",UPPER('Raw data for Day5'!C4),IF('Raw data for Day5'!C4="sales",PROPER('Raw data for Day5'!C4),IF('Raw data for Day5'!C4="marketing",PROPER('Raw data for Day5'!C4),"Un-known"))))))) -> HR | E4: =CLEAN(TRIM(IF('Raw data for Day5'!D4="germany",PROPER('Raw data for Day5'!D4),IF('Raw data for Day5'!D4="usa",UPPER('Raw data for Day5'!D4),IF('Raw data for Day5'!D4="uk",UPPER('Raw data for Day5'!D4),IF('Raw data for Day5'!D4="india",PROPER('Raw data for Day5'!D4),'Raw data for Day5'!D4)))))) -> Germany | F4: ='Raw data for Day5'!E4 -> 54255 | G4: ='Raw data for Day5'!F4 -> 42015 | H4: =CLEAN(TRIM('Raw data for Day5'!G4)) -> 1 | I4: =CLEAN(TRIM('Raw data for Day5'!H4)) -> Other | J4: =CLEAN(TRIM(LOWER('Raw data for Day5'!I4))) -> user106@example.com
A5: =CLEAN(TRIM(LEFT('Raw data for Day5'!A5,3))) -> EMP | B5: =CLEAN(TRIM(RIGHT('Raw data for Day5'!A5,4))) -> 1002 | C5: =CLEAN(TRIM(PROPER('Raw data for Day5'!B5))) -> Alice Brown | D5: =CLEAN(TRIM(IF('Raw data for Day5'!C5="finance",PROPER('Raw data for Day5'!C5),IF('Raw data for Day5'!C5="hr", UPPER('Raw data for Day5'!C5),IF('Raw data for Day5'!C5="it",UPPER('Raw data for Day5'!C5),IF('Raw data for Day5'!C5="sales",PROPER('Raw data for Day5'!C5),IF('Raw data for Day5'!C5="marketing",PROPER('Raw data for Day5'!C5),"Un-known"))))))) -> Finance | E5: =CLEAN(TRIM(IF('Raw data for Day5'!D5="germany",PROPER('Raw data for Day5'!D5),IF('Raw data for Day5'!D5="usa",UPPER('Raw data for Day5'!D5),IF('Raw data for Day5'!D5="uk",UPPER('Raw data for Day5'!D5),IF('Raw data for Day5'!D5="india",PROPER('Raw data for Day5'!D5),'Raw data for Day5'!D5)))))) -> Germany | F5: ='Raw data for Day5'!E5 -> 63184 | G5: ='Raw data for Day5'!F5 -> 42022 | H5: =CLEAN(TRIM('Raw data for Day5'!G5)) -> 2 | I5: =CLEAN(TRIM('Raw data for Day5'!H5)) -> Un-known | J5: =CLEAN(TRIM(LOWER('Raw data for Day5'!I5))) -> user176@example.com | L5: Names | M5: By using PROPER() each word was capitalised in Names Column
A6: =CLEAN(TRIM(LEFT('Raw data for Day5'!A6,3))) -> EMP | B6: =CLEAN(TRIM(RIGHT('Raw data for Day5'!A6,4))) -> 1003 | C6: =CLEAN(TRIM(PROPER('Raw data for Day5'!B6))) -> John Doe | D6: =CLEAN(TRIM(IF('Raw data for Day5'!C6="finance",PROPER('Raw data for Day5'!C6),IF('Raw data for Day5'!C6="hr", UPPER('Raw data for Day5'!C6),IF('Raw data for Day5'!C6="it",UPPER('Raw data for Day5'!C6),IF('Raw data for Day5'!C6="sales",PROPER('Raw data for Day5'!C6),IF('Raw data for Day5'!C6="marketing",PROPER('Raw data for Day5'!C6),"Un-known"))))))) -> Sales | E6: =CLEAN(TRIM(IF('Raw data for Day5'!D6="germany",PROPER('Raw data for Day5'!D6),IF('Raw data for Day5'!D6="usa",UPPER('Raw data for Day5'!D6),IF('Raw data for Day5'!D6="uk",UPPER('Raw data for Day5'!D6),IF('Raw data for Day5'!D6="india",PROPER('Raw data for Day5'!D6),'Raw data for Day5'!D6)))))) -> USA | F6: ='Raw data for Day5'!E6 -> 94406 | G6: ='Raw data for Day5'!F6 -> 42029 | H6: =CLEAN(TRIM('Raw data for Day5'!G6)) -> 1 | I6: =CLEAN(TRIM('Raw data for Day5'!H6)) -> Male | J6: =CLEAN(TRIM(LOWER('Raw data for Day5'!I6))) -> user168@example.com | L6: Department | M6: The IF() was applied along with PROPER() and UPPER() to format text fields as required by the conditional logic.
A7: =CLEAN(TRIM(LEFT('Raw data for Day5'!A7,3))) -> EMP | B7: =CLEAN(TRIM(RIGHT('Raw data for Day5'!A7,4))) -> 1004 | C7: =CLEAN(TRIM(PROPER('Raw data for Day5'!B7))) -> Jane Smith | D7: =CLEAN(TRIM(IF('Raw data for Day5'!C7="finance",PROPER('Raw data for Day5'!C7),IF('Raw data for Day5'!C7="hr", UPPER('Raw data for Day5'!C7),IF('Raw data for Day5'!C7="it",UPPER('Raw data for Day5'!C7),IF('Raw data for Day5'!C7="sales",PROPER('Raw data for Day5'!C7),IF('Raw data for Day5'!C7="marketing",PROPER('Raw data for Day5'!C7),"Un-known"))))))) -> Sales | E7: =CLEAN(TRIM(IF('Raw data for Day5'!D7="germany",PROPER('Raw data for Day5'!D7),IF('Raw data for Day5'!D7="usa",UPPER('Raw data for Day5'!D7),IF('Raw data for Day5'!D7="uk",UPPER('Raw data for Day5'!D7),IF('Raw data for Day5'!D7="india",PROPER('Raw data for Day5'!D7),'Raw data for Day5'!D7)))))) -> Germany | F7: ='Raw data for Day5'!E7 -> 64120 | G7: ='Raw data for Day5'!F7 -> 42036 | H7: =CLEAN(TRIM('Raw data for Day5'!G7)) -> 1 | I7: =CLEAN(TRIM('Raw data for Day5'!H7)) -> Male | J7: =CLEAN(TRIM(LOWER('Raw data for Day5'!I7))) -> user49@example.com
A8: =CLEAN(TRIM(LEFT('Raw data for Day5'!A8,3))) -> EMP | B8: =CLEAN(TRIM(RIGHT('Raw data for Day5'!A8,4))) -> 1005 | C8: =CLEAN(TRIM(PROPER('Raw data for Day5'!B8))) -> Alice Brown | D8: =CLEAN(TRIM(IF('Raw data for Day5'!C8="finance",PROPER('Raw data for Day5'!C8),IF('Raw data for Day5'!C8="hr", UPPER('Raw data for Day5'!C8),IF('Raw data for Day5'!C8="it",UPPER('Raw data for Day5'!C8),IF('Raw data for Day5'!C8="sales",PROPER('Raw data for Day5'!C8),IF('Raw data for Day5'!C8="marketing",PROPER('Raw data for Day5'!C8),"Un-known"))))))) -> IT | E8: =CLEAN(TRIM(IF('Raw data for Day5'!D8="germany",PROPER('Raw data for Day5'!D8),IF('Raw data for Day5'!D8="usa",UPPER('Raw data for Day5'!D8),IF('Raw data for Day5'!D8="uk",UPPER('Raw data for Day5'!D8),IF('Raw data for Day5'!D8="india",PROPER('Raw data for Day5'!D8),'Raw data for Day5'!D8)))))) -> India | F8: ='Raw data for Day5'!E8 -> 78421 | G8: ='Raw data for Day5'!F8 -> 42043 | H8: =CLEAN(TRIM('Raw data for Day5'!G8)) -> 2 | I8: =CLEAN(TRIM('Raw data for Day5'!H8)) -> Female | J8: =CLEAN(TRIM(LOWER('Raw data for Day5'!I8))) -> user24@example.com | L8: Country | M8: The IF() was applied along with PROPER() and UPPER() to format text fields as required by the conditional logic.
A9: =CLEAN(TRIM(LEFT('Raw data for Day5'!A9,3))) -> EMP | B9: =CLEAN(TRIM(RIGHT('Raw data for Day5'!A9,4))) -> 1006 | C9: =CLEAN(TRIM(PROPER('Raw data for Day5'!B9))) -> Sam Wilson | D9: =CLEAN(TRIM(IF('Raw data for Day5'!C9="finance",PROPER('Raw data for Day5'!C9),IF('Raw data for Day5'!C9="hr", UPPER('Raw data for Day5'!C9),IF('Raw data for Day5'!C9="it",UPPER('Raw data for Day5'!C9),IF('Raw data for Day5'!C9="sales",PROPER('Raw data for Day5'!C9),IF('Raw data for Day5'!C9="marketing",PROPER('Raw data for Day5'!C9),"Un-known"))))))) -> Sales | E9: =CLEAN(TRIM(IF('Raw data for Day5'!D9="germany",PROPER('Raw data for Day5'!D9),IF('Raw data for Day5'!D9="usa",UPPER('Raw data for Day5'!D9),IF('Raw data for Day5'!D9="uk",UPPER('Raw data for Day5'!D9),IF('Raw data for Day5'!D9="india",PROPER('Raw data for Day5'!D9),'Raw data for Day5'!D9)))))) -> Un-known | F9: ='Raw data for Day5'!E9 -> 67721 | G9: ='Raw data for Day5'!F9 -> 42050 | H9: =CLEAN(TRIM('Raw data for Day5'!G9)) -> N/A | I9: =CLEAN(TRIM('Raw data for Day5'!H9)) -> Male | J9: =CLEAN(TRIM(LOWER('Raw data for Day5'!I9))) -> user168@example.com
A10: =CLEAN(TRIM(LEFT('Raw data for Day5'!A10,3))) -> EMP | B10: =CLEAN(TRIM(RIGHT('Raw data for Day5'!A10,4))) -> 1007 | C10: =CLEAN(TRIM(PROPER('Raw data for Day5'!B10))) -> Chris Lee | D10: =CLEAN(TRIM(IF('Raw data for Day5'!C10="finance",PROPER('Raw data for Day5'!C10),IF('Raw data for Day5'!C10="hr", UPPER('Raw data for Day5'!C10),IF('Raw data for Day5'!C10="it",UPPER('Raw data for Day5'!C10),IF('Raw data for Day5'!C10="sales",PROPER('Raw data for Day5'!C10),IF('Raw data for Day5'!C10="marketing",PROPER('Raw data for Day5'!C10),"Un-known"))))))) -> Marketing | E10: =CLEAN(TRIM(IF('Raw data for Day5'!D10="germany",PROPER('Raw data for Day5'!D10),IF('Raw data for Day5'!D10="usa",UPPER('Raw data for Day5'!D10),IF('Raw data for Day5'!D10="uk",UPPER('Raw data for Day5'!D10),IF('Raw data for Day5'!D10="india",PROPER('Raw data for Day5'!D10),'Raw data for Day5'!D10)))))) -> Un-known | F10: ='Raw data for Day5'!E10 -> 35364 | G10: ='Raw data for Day5'!F10 -> 42057 | H10: =CLEAN(TRIM('Raw data for Day5'!G10)) -> 2 | I10: =CLEAN(TRIM('Raw data for Day5'!H10)) -> Other | J10: =CLEAN(TRIM(LOWER('Raw data for Day5'!I10))) -> user26@example.com | L10: Email | M10: The Email column was standardized by applying the LOWER() function to ensure all values are in lowercase format.
A11: =CLEAN(TRIM(LEFT('Raw data for Day5'!A11,3))) -> EMP | B11: =CLEAN(TRIM(RIGHT('Raw data for Day5'!A11,4))) -> 1008 | C11: =CLEAN(TRIM(PROPER('Raw data for Day5'!B11))) -> Alice Brown | D11: =CLEAN(TRIM(IF('Raw data for Day5'!C11="finance",PROPER('Raw data for Day5'!C11),IF('Raw data for Day5'!C11="hr", UPPER('Raw data for Day5'!C11),IF('Raw data for Day5'!C11="it",UPPER('Raw data for Day5'!C11),IF('Raw data for Day5'!C11="sales",PROPER('Raw data for Day5'!C11),IF('Raw data for Day5'!C11="marketing",PROPER('Raw data for Day5'!C11),"Un-known"))))))) -> IT | E11: =CLEAN(TRIM(IF('Raw data for Day5'!D11="germany",PROPER('Raw data for Day5'!D11),IF('Raw data for Day5'!D11="usa",UPPER('Raw data for Day5'!D11),IF('Raw data for Day5'!D11="uk",UPPER('Raw data for Day5'!D11),IF('Raw data for Day5'!D11="india",PROPER('Raw data for Day5'!D11),'Raw data for Day5'!D11)))))) -> Germany | F11: ='Raw data for Day5'!E11 -> 97881 | G11: ='Raw data for Day5'!F11 -> 42064 | H11: =CLEAN(TRIM('Raw data for Day5'!G11)) -> N/A | I11: =CLEAN(TRIM('Raw data for Day5'!H11)) -> Female | J11: =CLEAN(TRIM(LOWER('Raw data for Day5'!I11))) -> user25@example.com
A12: =CLEAN(TRIM(LEFT('Raw data for Day5'!A12,3))) -> EMP | B12: =CLEAN(TRIM(RIGHT('Raw data for Day5'!A12,4))) -> 1009 | C12: =CLEAN(TRIM(PROPER('Raw data for Day5'!B12))) -> Chris Lee | D12: =CLEAN(TRIM(IF('Raw data for Day5'!C12="finance",PROPER('Raw data for Day5'!C12),IF('Raw data for Day5'!C12="hr", UPPER('Raw data for Day5'!C12),IF('Raw data for Day5'!C12="it",UPPER('Raw data for Day5'!C12),IF('Raw data for Day5'!C12="sales",PROPER('Raw data for Day5'!C12),IF('Raw data for Day5'!C12="marketing",PROPER('Raw data for Day5'!C12),"Un-known"))))))) -> HR | E12: =CLEAN(TRIM(IF('Raw data for Day5'!D12="germany",PROPER('Raw data for Day5'!D12),IF('Raw data for Day5'!D12="usa",UPPER('Raw data for Day5'!D12),IF('Raw data for Day5'!D12="uk",UPPER('Raw data for Day5'!D12),IF('Raw data for Day5'!D12="india",PROPER('Raw data for Day5'!D12),'Raw data for Day5'!D12)))))) -> UK | F12: ='Raw data for Day5'!E12 -> 91846 | G12: ='Raw data for Day5'!F12 -> 42071 | H12: =CLEAN(TRIM('Raw data for Day5'!G12)) -> N/A | I12: =CLEAN(TRIM('Raw data for Day5'!H12)) -> Male | J12: =CLEAN(TRIM(LOWER('Raw data for Day5'!I12))) -> user153@example.com | L12: Salary | M12: By using CLEAN() & TRIM() unwanted characters were removed and formatted to Currency data type.
A13: =CLEAN(TRIM(LEFT('Raw data for Day5'!A13,3))) -> EMP | B13: =CLEAN(TRIM(RIGHT('Raw data for Day5'!A13,4))) -> 1010 | C13: =CLEAN(TRIM(PROPER('Raw data for Day5'!B13))) -> Sam Wilson | D13: =CLEAN(TRIM(IF('Raw data for Day5'!C13="finance",PROPER('Raw data for Day5'!C13),IF('Raw data for Day5'!C13="hr", UPPER('Raw data for Day5'!C13),IF('Raw data for Day5'!C13="it",UPPER('Raw data for Day5'!C13),IF('Raw data for Day5'!C13="sales",PROPER('Raw data for Day5'!C13),IF('Raw data for Day5'!C13="marketing",PROPER('Raw data for Day5'!C13),"Un-known"))))))) -> Finance | E13: =CLEAN(TRIM(IF('Raw data for Day5'!D13="germany",PROPER('Raw data for Day5'!D13),IF('Raw data for Day5'!D13="usa",UPPER('Raw data for Day5'!D13),IF('Raw data for Day5'!D13="uk",UPPER('Raw data for Day5'!D13),IF('Raw data for Day5'!D13="india",PROPER('Raw data for Day5'!D13),'Raw data for Day5'!D13)))))) -> UK | F13: ='Raw data for Day5'!E13 -> 64247 | G13: ='Raw data for Day5'!F13 -> 42078 | H13: =CLEAN(TRIM('Raw data for Day5'!G13)) -> 1 | I13: =CLEAN(TRIM('Raw data for Day5'!H13)) -> Female | J13: =CLEAN(TRIM(LOWER('Raw data for Day5'!I13))) -> user18@example.com
A14: =CLEAN(TRIM(LEFT('Raw data for Day5'!A14,3))) -> EMP | B14: =CLEAN(TRIM(RIGHT('Raw data for Day5'!A14,4))) -> 1011 | C14: =CLEAN(TRIM(PROPER('Raw data for Day5'!B14))) -> Sam Wilson | D14: =CLEAN(TRIM(IF('Raw data for Day5'!C14="finance",PROPER('Raw data for Day5'!C14),IF('Raw data for Day5'!C14="hr", UPPER('Raw data for Day5'!C14),IF('Raw data for Day5'!C14="it",UPPER('Raw data for Day5'!C14),IF('Raw data for Day5'!C14="sales",PROPER('Raw data for Day5'!C14),IF('Raw data for Day5'!C14="marketing",PROPER('Raw data for Day5'!C14),"Un-known"))))))) -> IT | E14: =CLEAN(TRIM(IF('Raw data for Day5'!D14="germany",PROPER('Raw data for Day5'!D14),IF('Raw data for Day5'!D14="usa",UPPER('Raw data for Day5'!D14),IF('Raw data for Day5'!D14="uk",UPPER('Raw data for Day5'!D14),IF('Raw data for Day5'!D14="india",PROPER('Raw data for Day5'!D14),'Raw data for Day5'!D14)))))) -> USA | F14: ='Raw data for Day5'!E14 -> 91180 | G14: ='Raw data for Day5'!F14 -> 42085 | H14: =CLEAN(TRIM('Raw data for Day5'!G14)) -> 5 | I14: =CLEAN(TRIM('Raw data for Day5'!H14)) -> Male | J14: =CLEAN(TRIM(LOWER('Raw data for Day5'!I14))) -> user1@example.com | L14: Date of Joining | M14: Values were extracted from raw dataset and converted to Date data type.
A15: =CLEAN(TRIM(LEFT('Raw data for Day5'!A15,3))) -> EMP | B15: =CLEAN(TRIM(RIGHT('Raw data for Day5'!A15,4))) -> 1012 | C15: =CLEAN(TRIM(PROPER('Raw data for Day5'!B15))) -> Bob Johnson | D15: =CLEAN(TRIM(IF('Raw data for Day5'!C15="finance",PROPER('Raw data for Day5'!C15),IF('Raw data for Day5'!C15="hr", UPPER('Raw data for Day5'!C15),IF('Raw data for Day5'!C15="it",UPPER('Raw data for Day5'!C15),IF('Raw data for Day5'!C15="sales",PROPER('Raw data for Day5'!C15),IF('Raw data for Day5'!C15="marketing",PROPER('Raw data for Day5'!C15),"Un-known"))))))) -> Sales | E15: =CLEAN(TRIM(IF('Raw data for Day5'!D15="germany",PROPER('Raw data for Day5'!D15),IF('Raw data for Day5'!D15="usa",UPPER('Raw data for Day5'!D15),IF('Raw data for Day5'!D15="uk",UPPER('Raw data for Day5'!D15),IF('Raw data for Day5'!D15="india",PROPER('Raw data for Day5'!D15),'Raw data for Day5'!D15)))))) -> Un-known | F15: ='Raw data for Day5'!E15 -> 96418 | G15: ='Raw data for Day5'!F15 -> 42092 | H15: =CLEAN(TRIM('Raw data for Day5'!G15)) -> 5 | I15: =CLEAN(TRIM('Raw data for Day5'!H15)) -> Male | J15: =CLEAN(TRIM(LOWER('Raw data for Day5'!I15))) -> user106@example.com | L15: Performance Rating | M15: By using CLEAN() & TRIM() unwanted characters were removed and formatted to Text data type.
A16: =CLEAN(TRIM(LEFT('Raw data for Day5'!A16,3))) -> EMP | B16: =CLEAN(TRIM(RIGHT('Raw data for Day5'!A16,4))) -> 1013 | C16: =CLEAN(TRIM(PROPER('Raw data for Day5'!B16))) -> Sam Wilson | D16: =CLEAN(TRIM(IF('Raw data for Day5'!C16="finance",PROPER('Raw data for Day5'!C16),IF('Raw data for Day5'!C16="hr", UPPER('Raw data for Day5'!C16),IF('Raw data for Day5'!C16="it",UPPER('Raw data for Day5'!C16),IF('Raw data for Day5'!C16="sales",PROPER('Raw data for Day5'!C16),IF('Raw data for Day5'!C16="marketing",PROPER('Raw data for Day5'!C16),"Un-known"))))))) -> Un-known | E16: =CLEAN(TRIM(IF('Raw data for Day5'!D16="germany",PROPER('Raw data for Day5'!D16),IF('Raw data for Day5'!D16="usa",UPPER('Raw data for Day5'!D16),IF('Raw data for Day5'!D16="uk",UPPER('Raw data for Day5'!D16),IF('Raw data for Day5'!D16="india",PROPER('Raw data for Day5'!D16),'Raw data for Day5'!D16)))))) -> India | F16: ='Raw data for Day5'!E16 -> 62158 | G16: ='Raw data for Day5'!F16 -> 42099 | H16: =CLEAN(TRIM('Raw data for Day5'!G16)) -> 4 | I16: =CLEAN(TRIM('Raw data for Day5'!H16)) -> Un-known | J16: =CLEAN(TRIM(LOWER('Raw data for Day5'!I16))) -> user180@example.com
A17: =CLEAN(TRIM(LEFT('Raw data for Day5'!A17,3))) -> EMP | B17: =CLEAN(TRIM(RIGHT('Raw data for Day5'!A17,4))) -> 1014 | C17: =CLEAN(TRIM(PROPER('Raw data for Day5'!B17))) -> Jane Smith | D17: =CLEAN(TRIM(IF('Raw data for Day5'!C17="finance",PROPER('Raw data for Day5'!C17),IF('Raw data for Day5'!C17="hr", UPPER('Raw data for Day5'!C17),IF('Raw data for Day5'!C17="it",UPPER('Raw data for Day5'!C17),IF('Raw data for Day5'!C17="sales",PROPER('Raw data for Day5'!C17),IF('Raw data for Day5'!C17="marketing",PROPER('Raw data for Day5'!C17),"Un-known"))))))) -> HR | E17: =CLEAN(TRIM(IF('Raw data for Day5'!D17="germany",PROPER('Raw data for Day5'!D17),IF('Raw data for Day5'!D17="usa",UPPER('Raw data for Day5'!D17),IF('Raw data for Day5'!D17="uk",UPPER('Raw data for Day5'!D17),IF('Raw data for Day5'!D17="india",PROPER('Raw data for Day5'!D17),'Raw data for Day5'!D17)))))) -> Un-known | F17: ='Raw data for Day5'!E17 -> 59894 | G17: ='Raw data for Day5'!F17 -> 42106 | H17: =CLEAN(TRIM('Raw data for Day5'!G17)) -> 2 | I17: =CLEAN(TRIM('Raw data for Day5'!H17)) -> Male | J17: =CLEAN(TRIM(LOWER('Raw data for Day5'!I17))) -> user184@example.com | L17: Gender | M17: By using CLEAN() & TRIM() unwanted characters were removed and formatted to Text data type.
A18: =CLEAN(TRIM(LEFT('Raw data for Day5'!A18,3))) -> EMP | B18: =CLEAN(TRIM(RIGHT('Raw data for Day5'!A18,4))) -> 1015 | C18: =CLEAN(TRIM(PROPER('Raw data for Day5'!B18))) -> Un-Known | D18: =CLEAN(TRIM(IF('Raw data for Day5'!C18="finance",PROPER('Raw data for Day5'!C18),IF('Raw data for Day5'!C18="hr", UPPER('Raw data for Day5'!C18),IF('Raw data for Day5'!C18="it",UPPER('Raw data for Day5'!C18),IF('Raw data for Day5'!C18="sales",PROPER('Raw data for Day5'!C18),IF('Raw data for Day5'!C18="marketing",PROPER('Raw data for Day5'!C18),"Un-known"))))))) -> IT | E18: =CLEAN(TRIM(IF('Raw data for Day5'!D18="germany",PROPER('Raw data for Day5'!D18),IF('Raw data for Day5'!D18="usa",UPPER('Raw data for Day5'!D18),IF('Raw data for Day5'!D18="uk",UPPER('Raw data for Day5'!D18),IF('Raw data for Day5'!D18="india",PROPER('Raw data for Day5'!D18),'Raw data for Day5'!D18)))))) -> India | F18: ='Raw data for Day5'!E18 -> 92443 | G18: ='Raw data for Day5'!F18 -> 42113 | H18: =CLEAN(TRIM('Raw data for Day5'!G18)) -> 3 | I18: =CLEAN(TRIM('Raw data for Day5'!H18)) -> Other | J18: =CLEAN(TRIM(LOWER('Raw data for Day5'!I18))) -> user3@example.com
A19: =CLEAN(TRIM(LEFT('Raw data for Day5'!A19,3))) -> EMP | B19: =CLEAN(TRIM(RIGHT('Raw data for Day5'!A19,4))) -> 1016 | C19: =CLEAN(TRIM(PROPER('Raw data for Day5'!B19))) -> Bob Johnson | D19: =CLEAN(TRIM(IF('Raw data for Day5'!C19="finance",PROPER('Raw data for Day5'!C19),IF('Raw data for Day5'!C19="hr", UPPER('Raw data for Day5'!C19),IF('Raw data for Day5'!C19="it",UPPER('Raw data for Day5'!C19),IF('Raw data for Day5'!C19="sales",PROPER('Raw data for Day5'!C19),IF('Raw data for Day5'!C19="marketing",PROPER('Raw data for Day5'!C19),"Un-known"))))))) -> Un-known | E19: =CLEAN(TRIM(IF('Raw data for Day5'!D19="germany",PROPER('Raw data for Day5'!D19),IF('Raw data for Day5'!D19="usa",UPPER('Raw data for Day5'!D19),IF('Raw data for Day5'!D19="uk",UPPER('Raw data for Day5'!D19),IF('Raw data for Day5'!D19="india",PROPER('Raw data for Day5'!D19),'Raw data for Day5'!D19)))))) -> Germany | F19: ='Raw data for Day5'!E19 -> 90271 | G19: ='Raw data for Day5'!F19 -> 42120 | H19: =CLEAN(TRIM('Raw data for Day5'!G19)) -> N/A | I19: =CLEAN(TRIM('Raw data for Day5'!H19)) -> Un-known | J19: =CLEAN(TRIM(LOWER('Raw data for Day5'!I19))) -> user64@example.com
A20: =CLEAN(TRIM(LEFT('Raw data for Day5'!A20,3))) -> EMP | B20: =CLEAN(TRIM(RIGHT('Raw data for Day5'!A20,4))) -> 1017 | C20: =CLEAN(TRIM(PROPER('Raw data for Day5'!B20))) -> Jane Smith | D20: =CLEAN(TRIM(IF('Raw data for Day5'!C20="finance",PROPER('Raw data for Day5'!C20),IF('Raw data for Day5'!C20="hr", UPPER('Raw data for Day5'!C20),IF('Raw data for Day5'!C20="it",UPPER('Raw data for Day5'!C20),IF('Raw data for Day5'!C20="sales",PROPER('Raw data for Day5'!C20),IF('Raw data for Day5'!C20="marketing",PROPER('Raw data for Day5'!C20),"Un-known"))))))) -> Finance | E20: =CLEAN(TRIM(IF('Raw data for Day5'!D20="germany",PROPER('Raw data for Day5'!D20),IF('Raw data for Day5'!D20="usa",UPPER('Raw data for Day5'!D20),IF('Raw data for Day5'!D20="uk",UPPER('Raw data for Day5'!D20),IF('Raw data for Day5'!D20="india",PROPER('Raw data for Day5'!D20),'Raw data for Day5'!D20)))))) -> Australia | F20: ='Raw data for Day5'!E20 -> 41341 | G20: ='Raw data for Day5'!F20 -> 42127 | H20: =CLEAN(TRIM('Raw data for Day5'!G20)) -> 1 | I20: =CLEAN(TRIM('Raw data for Day5'!H20)) -> Other | J20: =CLEAN(TRIM(LOWER('Raw data for Day5'!I20))) -> user38@example.com | L20: NOTE : CLEAN() and TRIM() were applied across all columns while formatting.
A21: =CLEAN(TRIM(LEFT('Raw data for Day5'!A21,3))) -> EMP | B21: =CLEAN(TRIM(RIGHT('Raw data for Day5'!A21,4))) -> 1018 | C21: =CLEAN(TRIM(PROPER('Raw data for Day5'!B21))) -> Alice Brown | D21: =CLEAN(TRIM(IF('Raw data for Day5'!C21="finance",PROPER('Raw data for Day5'!C21),IF('Raw data for Day5'!C21="hr", UPPER('Raw data for Day5'!C21),IF('Raw data for Day5'!C21="it",UPPER('Raw data for Day5'!C21),IF('Raw data for Day5'!C21="sales",PROPER('Raw data for Day5'!C21),IF('Raw data for Day5'!C21="marketing",PROPER('Raw data for Day5'!C21),"Un-known"))))))) -> Finance | E21: =CLEAN(TRIM(IF('Raw data for Day5'!D21="germany",PROPER('Raw data for Day5'!D21),IF('Raw data for Day5'!D21="usa",UPPER('Raw data for Day5'!D21),IF('Raw data for Day5'!D21="uk",UPPER('Raw data for Day5'!D21),IF('Raw data for Day5'!D21="india",PROPER('Raw data for Day5'!D21),'Raw data for Day5'!D21)))))) -> UK | F21: ='Raw data for Day5'!E21 -> 73602 | G21: ='Raw data for Day5'!F21 -> 42134 | H21: =CLEAN(TRIM('Raw data for Day5'!G21)) -> N/A | I21: =CLEAN(TRIM('Raw data for Day5'!H21)) -> Un-known | J21: =CLEAN(TRIM(LOWER('Raw data for Day5'!I21))) -> user96@example.com
A22: =CLEAN(TRIM(LEFT('Raw data for Day5'!A22,3))) -> EMP | B22: =CLEAN(TRIM(RIGHT('Raw data for Day5'!A22,4))) -> 1019 | C22: =CLEAN(TRIM(PROPER('Raw data for Day5'!B22))) -> Eve Adams | D22: =CLEAN(TRIM(IF('Raw data for Day5'!C22="finance",PROPER('Raw data for Day5'!C22),IF('Raw data for Day5'!C22="hr", UPPER('Raw data for Day5'!C22),IF('Raw data for Day5'!C22="it",UPPER('Raw data for Day5'!C22),IF('Raw data for Day5'!C22="sales",PROPER('Raw data for Day5'!C22),IF('Raw data for Day5'!C22="marketing",PROPER('Raw data for Day5'!C22),"Un-known"))))))) -> Un-known | E22: =CLEAN(TRIM(IF('Raw data for Day5'!D22="germany",PROPER('Raw data for Day5'!D22),IF('Raw data for Day5'!D22="usa",UPPER('Raw data for Day5'!D22),IF('Raw data for Day5'!D22="uk",UPPER('Raw data for Day5'!D22),IF('Raw data for Day5'!D22="india",PROPER('Raw data for Day5'!D22),'Raw data for Day5'!D22)))))) -> India | F22: ='Raw data for Day5'!E22 -> 67531 | G22: ='Raw data for Day5'!F22 -> 42141 | H22: =CLEAN(TRIM('Raw data for Day5'!G22)) -> 5 | I22: =CLEAN(TRIM('Raw data for Day5'!H22)) -> Female | J22: =CLEAN(TRIM(LOWER('Raw data for Day5'!I22))) -> user151@example.com
A23: =CLEAN(TRIM(LEFT('Raw data for Day5'!A23,3))) -> EMP | B23: =CLEAN(TRIM(RIGHT('Raw data for Day5'!A23,4))) -> 1020 | C23: =CLEAN(TRIM(PROPER('Raw data for Day5'!B23))) -> Jane Smith | D23: =CLEAN(TRIM(IF('Raw data for Day5'!C23="finance",PROPER('Raw data for Day5'!C23),IF('Raw data for Day5'!C23="hr", UPPER('Raw data for Day5'!C23),IF('Raw data for Day5'!C23="it",UPPER('Raw data for Day5'!C23),IF('Raw data for Day5'!C23="sales",PROPER('Raw data for Day5'!C23),IF('Raw data for Day5'!C23="marketing",PROPER('Raw data for Day5'!C23),"Un-known"))))))) -> HR | E23: =CLEAN(TRIM(IF('Raw data for Day5'!D23="germany",PROPER('Raw data for Day5'!D23),IF('Raw data for Day5'!D23="usa",UPPER('Raw data for Day5'!D23),IF('Raw data for Day5'!D23="uk",UPPER('Raw data for Day5'!D23),IF('Raw data for Day5'!D23="india",PROPER('Raw data for Day5'!D23),'Raw data for Day5'!D23)))))) -> USA | F23: ='Raw data for Day5'!E23 -> 0 | G23: ='Raw data for Day5'!F23 -> 42148 | H23: =CLEAN(TRIM('Raw data for Day5'!G23)) -> 2 | I23: =CLEAN(TRIM('Raw data for Day5'!H23)) -> Other | J23: =CLEAN(TRIM(LOWER('Raw data for Day5'!I23))) -> user200@example.com
A24: =CLEAN(TRIM(LEFT('Raw data for Day5'!A24,3))) -> EMP | B24: =CLEAN(TRIM(RIGHT('Raw data for Day5'!A24,4))) -> 1021 | C24: =CLEAN(TRIM(PROPER('Raw data for Day5'!B24))) -> Jane Smith | D24: =CLEAN(TRIM(IF('Raw data for Day5'!C24="finance",PROPER('Raw data for Day5'!C24),IF('Raw data for Day5'!C24="hr", UPPER('Raw data for Day5'!C24),IF('Raw data for Day5'!C24="it",UPPER('Raw data for Day5'!C24),IF('Raw data for Day5'!C24="sales",PROPER('Raw data for Day5'!C24),IF('Raw data for Day5'!C24="marketing",PROPER('Raw data for Day5'!C24),"Un-known"))))))) -> HR | E24: =CLEAN(TRIM(IF('Raw data for Day5'!D24="germany",PROPER('Raw data for Day5'!D24),IF('Raw data for Day5'!D24="usa",UPPER('Raw data for Day5'!D24),IF('Raw data for Day5'!D24="uk",UPPER('Raw data for Day5'!D24),IF('Raw data for Day5'!D24="india",PROPER('Raw data for Day5'!D24),'Raw data for Day5'!D24)))))) -> Un-known | F24: ='Raw data for Day5'!E24 -> 98922 | G24: ='Raw data for Day5'!F24 -> 42155 | H24: =CLEAN(TRIM('Raw data for Day5'!G24)) -> 4 | I24: =CLEAN(TRIM('Raw data for Day5'!H24)) -> Un-known | J24: =CLEAN(TRIM(LOWER('Raw data for Day5'!I24))) -> user77@example.com
A25: =CLEAN(TRIM(LEFT('Raw data for Day5'!A25,3))) -> EMP | B25: =CLEAN(TRIM(RIGHT('Raw data for Day5'!A25,4))) -> 1022 | C25: =CLEAN(TRIM(PROPER('Raw data for Day5'!B25))) -> Eve Adams | D25: =CLEAN(TRIM(IF('Raw data for Day5'!C25="finance",PROPER('Raw data for Day5'!C25),IF('Raw data for Day5'!C25="hr", UPPER('Raw data for Day5'!C25),IF('Raw data for Day5'!C25="it",UPPER('Raw data for Day5'!C25),IF('Raw data for Day5'!C25="sales",PROPER('Raw data for Day5'!C25),IF('Raw data for Day5'!C25="marketing",PROPER('Raw data for Day5'!C25),"Un-known"))))))) -> Finance | E25: =CLEAN(TRIM(IF('Raw data for Day5'!D25="germany",PROPER('Raw data for Day5'!D25),IF('Raw data for Day5'!D25="usa",UPPER('Raw data for Day5'!D25),IF('Raw data for Day5'!D25="uk",UPPER('Raw data for Day5'!D25),IF('Raw data for Day5'!D25="india",PROPER('Raw data for Day5'!D25),'Raw data for Day5'!D25)))))) -> India | F25: ='Raw data for Day5'!E25 -> 38333 | G25: ='Raw data for Day5'!F25 -> 42162 | H25: =CLEAN(TRIM('Raw data for Day5'!G25)) -> 5 | I25: =CLEAN(TRIM('Raw data for Day5'!H25)) -> Un-known | J25: =CLEAN(TRIM(LOWER('Raw data for Day5'!I25))) -> user128@example.com
A26: =CLEAN(TRIM(LEFT('Raw data for Day5'!A26,3))) -> EMP | B26: =CLEAN(TRIM(RIGHT('Raw data for Day5'!A26,4))) -> 1023 | C26: =CLEAN(TRIM(PROPER('Raw data for Day5'!B26))) -> Alice Brown | D26: =CLEAN(TRIM(IF('Raw data for Day5'!C26="finance",PROPER('Raw data for Day5'!C26),IF('Raw data for Day5'!C26="hr", UPPER('Raw data for Day5'!C26),IF('Raw data for Day5'!C26="it",UPPER('Raw data for Day5'!C26),IF('Raw data for Day5'!C26="sales",PROPER('Raw data for Day5'!C26),IF('Raw data for Day5'!C26="marketing",PROPER('Raw data for Day5'!C26),"Un-known"))))))) -> Marketing | E26: =CLEAN(TRIM(IF('Raw data for Day5'!D26="germany",PROPER('Raw data for Day5'!D26),IF('Raw data for Day5'!D26="usa",UPPER('Raw data for Day5'!D26),IF('Raw data for Day5'!D26="uk",UPPER('Raw data for Day5'!D26),IF('Raw data for Day5'!D26="india",PROPER('Raw data for Day5'!D26),'Raw data for Day5'!D26)))))) -> UK | F26: ='Raw data for Day5'!E26 -> 36515 | G26: ='Raw data for Day5'!F26 -> 42169 | H26: =CLEAN(TRIM('Raw data for Day5'!G26)) -> 3 | I26: =CLEAN(TRIM('Raw data for Day5'!H26)) -> Male | J26: =CLEAN(TRIM(LOWER('Raw data for Day5'!I26))) -> user149@example.com
A27: =CLEAN(TRIM(LEFT('Raw data for Day5'!A27,3))) -> EMP | B27: =CLEAN(TRIM(RIGHT('Raw data for Day5'!A27,4))) -> 1024 | C27: =CLEAN(TRIM(PROPER('Raw data for Day5'!B27))) -> Sam Wilson | D27: =CLEAN(TRIM(IF('Raw data for Day5'!C27="finance",PROPER('Raw data for Day5'!C27),IF('Raw data for Day5'!C27="hr", UPPER('Raw data for Day5'!C27),IF('Raw data for Day5'!C27="it",UPPER('Raw data for Day5'!C27),IF('Raw data for Day5'!C27="sales",PROPER('Raw data for Day5'!C27),IF('Raw data for Day5'!C27="marketing",PROPER('Raw data for Day5'!C27),"Un-known"))))))) -> Finance | E27: =CLEAN(TRIM(IF('Raw data for Day5'!D27="germany",PROPER('Raw data for Day5'!D27),IF('Raw data for Day5'!D27="usa",UPPER('Raw data for Day5'!D27),IF('Raw data for Day5'!D27="uk",UPPER('Raw data for Day5'!D27),IF('Raw data for Day5'!D27="india",PROPER('Raw data for Day5'!D27),'Raw data for Day5'!D27)))))) -> Un-known | F27: ='Raw data for Day5'!E27 -> 91005 | G27: ='Raw data for Day5'!F27 -> 42176 | H27: =CLEAN(TRIM('Raw data for Day5'!G27)) -> 1 | I27: =CLEAN(TRIM('Raw data for Day5'!H27)) -> Other | J27: =CLEAN(TRIM(LOWER('Raw data for Day5'!I27))) -> user122@example.com
A28: =CLEAN(TRIM(LEFT('Raw data for Day5'!A28,3))) -> EMP | B28: =CLEAN(TRIM(RIGHT('Raw data for Day5'!A28,4))) -> 1025 | C28: =CLEAN(TRIM(PROPER('Raw data for Day5'!B28))) -> Chris Lee | D28: =CLEAN(TRIM(IF('Raw data for Day5'!C28="finance",PROPER('Raw data for Day5'!C28),IF('Raw data for Day5'!C28="hr", UPPER('Raw data for Day5'!C28),IF('Raw data for Day5'!C28="it",UPPER('Raw data for Day5'!C28),IF('Raw data for Day5'!C28="sales",PROPER('Raw data for Day5'!C28),IF('Raw data for Day5'!C28="marketing",PROPER('Raw data for Day5'!C28),"Un-known"))))))) -> Un-known | E28: =CLEAN(TRIM(IF('Raw data for Day5'!D28="germany",PROPER('Raw data for Day5'!D28),IF('Raw data for Day5'!D28="usa",UPPER('Raw data for Day5'!D28),IF('Raw data for Day5'!D28="uk",UPPER('Raw data for Day5'!D28),IF('Raw data for Day5'!D28="india",PROPER('Raw data for Day5'!D28),'Raw data for Day5'!D28)))))) -> Un-known | F28: ='Raw data for Day5'!E28 -> 52272 | G28: ='Raw data for Day5'!F28 -> 42183 | H28: =CLEAN(TRIM('Raw data for Day5'!G28)) -> 3 | I28: =CLEAN(TRIM('Raw data for Day5'!H28)) -> Un-known | J28: =CLEAN(TRIM(LOWER('Raw data for Day5'!I28))) -> user41@example.com
A29: =CLEAN(TRIM(LEFT('Raw data for Day5'!A29,3))) -> EMP | B29: =CLEAN(TRIM(RIGHT('Raw data for Day5'!A29,4))) -> 1026 | C29: =CLEAN(TRIM(PROPER('Raw data for Day5'!B29))) -> Eve Adams | D29: =CLEAN(TRIM(IF('Raw data for Day5'!C29="finance",PROPER('Raw data for Day5'!C29),IF('Raw data for Day5'!C29="hr", UPPER('Raw data for Day5'!C29),IF('Raw data for Day5'!C29="it",UPPER('Raw data for Day5'!C29),IF('Raw data for Day5'!C29="sales",PROPER('Raw data for Day5'!C29),IF('Raw data for Day5'!C29="marketing",PROPER('Raw data for Day5'!C29),"Un-known"))))))) -> Sales | E29: =CLEAN(TRIM(IF('Raw data for Day5'!D29="germany",PROPER('Raw data for Day5'!D29),IF('Raw data for Day5'!D29="usa",UPPER('Raw data for Day5'!D29),IF('Raw data for Day5'!D29="uk",UPPER('Raw data for Day5'!D29),IF('Raw data for Day5'!D29="india",PROPER('Raw data for Day5'!D29),'Raw data for Day5'!D29)))))) -> Germany | F29: ='Raw data for Day5'!E29 -> 76518 | G29: ='Raw data for Day5'!F29 -> 42190 | H29: =CLEAN(TRIM('Raw data for Day5'!G29)) -> 2 | I29: =CLEAN(TRIM('Raw data for Day5'!H29)) -> Female | J29: =CLEAN(TRIM(LOWER('Raw data for Day5'!I29))) -> user68@example.com
A30: =CLEAN(TRIM(LEFT('Raw data for Day5'!A30,3))) -> EMP | B30: =CLEAN(TRIM(RIGHT('Raw data for Day5'!A30,4))) -> 1027 | C30: =CLEAN(TRIM(PROPER('Raw data for Day5'!B30))) -> Alice Brown | D30: =CLEAN(TRIM(IF('Raw data for Day5'!C30="finance",PROPER('Raw data for Day5'!C30),IF('Raw data for Day5'!C30="hr", UPPER('Raw data for Day5'!C30),IF('Raw data for Day5'!C30="it",UPPER('Raw data for Day5'!C30),IF('Raw data for Day5'!C30="sales",PROPER('Raw data for Day5'!C30),IF('Raw data for Day5'!C30="marketing",PROPER('Raw data for Day5'!C30),"Un-known"))))))) -> IT | E30: =CLEAN(TRIM(IF('Raw data for Day5'!D30="germany",PROPER('Raw data for Day5'!D30),IF('Raw data for Day5'!D30="usa",UPPER('Raw data for Day5'!D30),IF('Raw data for Day5'!D30="uk",UPPER('Raw data for Day5'!D30),IF('Raw data for Day5'!D30="india",PROPER('Raw data for Day5'!D30),'Raw data for Day5'!D30)))))) -> UK | F30: ='Raw data for Day5'!E30 -> 41448 | G30: ='Raw data for Day5'!F30 -> 42197 | H30: =CLEAN(TRIM('Raw data for Day5'!G30)) -> 3 | I30: =CLEAN(TRIM('Raw data for Day5'!H30)) -> Other | J30: =CLEAN(TRIM(LOWER('Raw data for Day5'!I30))) -> user103@example.com
A31: =CLEAN(TRIM(LEFT('Raw data for Day5'!A31,3))) -> EMP | B31: =CLEAN(TRIM(RIGHT('Raw data for Day5'!A31,4))) -> 1028 | C31: =CLEAN(TRIM(PROPER('Raw data for Day5'!B31))) -> John Doe | D31: =CLEAN(TRIM(IF('Raw data for Day5'!C31="finance",PROPER('Raw data for Day5'!C31),IF('Raw data for Day5'!C31="hr", UPPER('Raw data for Day5'!C31),IF('Raw data for Day5'!C31="it",UPPER('Raw data for Day5'!C31),IF('Raw data for Day5'!C31="sales",PROPER('Raw data for Day5'!C31),IF('Raw data for Day5'!C31="marketing",PROPER('Raw data for Day5'!C31),"Un-known"))))))) -> HR | E31: =CLEAN(TRIM(IF('Raw data for Day5'!D31="germany",PROPER('Raw data for Day5'!D31),IF('Raw data for Day5'!D31="usa",UPPER('Raw data for Day5'!D31),IF('Raw data for Day5'!D31="uk",UPPER('Raw data for Day5'!D31),IF('Raw data for Day5'!D31="india",PROPER('Raw data for Day5'!D31),'Raw data for Day5'!D31)))))) -> UK | F31: ='Raw data for Day5'!E31 -> 49282 | G31: ='Raw data for Day5'!F31 -> 42204 | H31: =CLEAN(TRIM('Raw data for Day5'!G31)) -> 2 | I31: =CLEAN(TRIM('Raw data for Day5'!H31)) -> Female | J31: =CLEAN(TRIM(LOWER('Raw data for Day5'!I31))) -> user135@example.com
A32: =CLEAN(TRIM(LEFT('Raw data for Day5'!A32,3))) -> EMP | B32: =CLEAN(TRIM(RIGHT('Raw data for Day5'!A32,4))) -> 1029 | C32: =CLEAN(TRIM(PROPER('Raw data for Day5'!B32))) -> Bob Johnson | D32: =CLEAN(TRIM(IF('Raw data for Day5'!C32="finance",PROPER('Raw data for Day5'!C32),IF('Raw data for Day5'!C32="hr", UPPER('Raw data for Day5'!C32),IF('Raw data for Day5'!C32="it",UPPER('Raw data for Day5'!C32),IF('Raw data for Day5'!C32="sales",PROPER('Raw data for Day5'!C32),IF('Raw data for Day5'!C32="marketing",PROPER('Raw data for Day5'!C32),"Un-known"))))))) -> Marketing | E32: =CLEAN(TRIM(IF('Raw data for Day5'!D32="germany",PROPER('Raw data for Day5'!D32),IF('Raw data for Day5'!D32="usa",UPPER('Raw data for Day5'!D32),IF('Raw data for Day5'!D32="uk",UPPER('Raw data for Day5'!D32),IF('Raw data for Day5'!D32="india",PROPER('Raw data for Day5'!D32),'Raw data for Day5'!D32)))))) -> UK | F32: ='Raw data for Day5'!E32 -> 92959 | G32: ='Raw data for Day5'!F32 -> 42211 | H32: =CLEAN(TRIM('Raw data for Day5'!G32)) -> 5 | I32: =CLEAN(TRIM('Raw data for Day5'!H32)) -> Un-known | J32: =CLEAN(TRIM(LOWER('Raw data for Day5'!I32))) -> user83@example.com
... A152: =CLEAN(TRIM(LEFT('Raw data for Day5'!A152,3))) -> EMP | B152: =CLEAN(TRIM(RIGHT('Raw data for Day5'!A152,4))) -> 1149 | C152: =CLEAN(TRIM(PROPER('Raw data for Day5'!B152))) -> Sam Wilson | D152: =CLEAN(TRIM(IF('Raw data for Day5'!C152="finance",PROPER('Raw data for Day5'!C152),IF('Raw data for Day5'!C152="hr", UPPER('Raw data for Day5'!C152),IF('Raw data for Day5'!C152="it",UPPER('Raw data for Day5'!C152),IF('Raw data for Day5'!C152="sales",PROPER('Raw data for Day5'!C152),IF('Raw data for Day5'!C152="marketing",PROPER('Raw data for Day5'!C152),"Un-known"))))))) -> Marketing | E152: =CLEAN(TRIM(IF('Raw data for Day5'!D152="germany",PROPER('Raw data for Day5'!D152),IF('Raw data for Day5'!D152="usa",UPPER('Raw data for Day5'!D152),IF('Raw data for Day5'!D152="uk",UPPER('Raw data for Day5'!D152),IF('Raw data for Day5'!D152="india",PROPER('Raw data for Day5'!D152),'Raw data for Day5'!D152)))))) -> India | F152: ='Raw data for Day5'!E152 -> 98475 | G152: ='Raw data for Day5'!F152 -> 43051 | H152: =CLEAN(TRIM('Raw data for Day5'!G152)) -> 5 | I152: =CLEAN(TRIM('Raw data for Day5'!H152)) -> Other | J152: =CLEAN(TRIM(LOWER('Raw data for Day5'!I152))) -> user30@example.com
A153: =CLEAN(TRIM(LEFT('Raw data for Day5'!A153,3))) | B153: =CLEAN(TRIM(RIGHT('Raw data for Day5'!A153,4))) | C153: =CLEAN(TRIM(PROPER('Raw data for Day5'!B153))) | E153: =CLEAN(TRIM(IF('Raw data for Day5'!D153="germany",PROPER('Raw data for Day5'!D153),IF('Raw data for Day5'!D153="usa",UPPER('Raw data for Day5'!D153),IF('Raw data for Day5'!D153="uk",UPPER('Raw data for Day5'!D153),IF('Raw data for Day5'!D153="india",PROPER('Raw data for Day5'!D153),'Raw data for Day5'!D153)))))) | F153: ='Raw data for Day5'!E153 -> 0 | G153: ='Raw data for Day5'!F153 -> 0 | H153: =CLEAN(TRIM('Raw data for Day5'!G153)) | I153: =CLEAN(TRIM('Raw data for Day5'!H153)) | J153: =CLEAN(TRIM(LOWER('Raw data for Day5'!I153)))
A154: =CLEAN(TRIM(LEFT('Raw data for Day5'!A154,3))) | B154: =CLEAN(TRIM(RIGHT('Raw data for Day5'!A154,4))) | C154: =CLEAN(TRIM(PROPER('Raw data for Day5'!B154))) | E154: =CLEAN(TRIM(IF('Raw data for Day5'!D154="germany",PROPER('Raw data for Day5'!D154),IF('Raw data for Day5'!D154="usa",UPPER('Raw data for Day5'!D154),IF('Raw data for Day5'!D154="uk",UPPER('Raw data for Day5'!D154),IF('Raw data for Day5'!D154="india",PROPER('Raw data for Day5'!D154),'Raw data for Day5'!D154)))))) | F154: ='Raw data for Day5'!E154 -> 0 | G154: ='Raw data for Day5'!F154 -> 0 | H154: =CLEAN(TRIM('Raw data for Day5'!G154)) | I154: =CLEAN(TRIM('Raw data for Day5'!H154)) | J154: =CLEAN(TRIM(LOWER('Raw data for Day5'!I154)))
A155: =CLEAN(TRIM(LEFT('Raw data for Day5'!A155,3))) | B155: =CLEAN(TRIM(RIGHT('Raw data for Day5'!A155,4))) | C155: =CLEAN(TRIM(PROPER('Raw data for Day5'!B155))) | E155: =CLEAN(TRIM(IF('Raw data for Day5'!D155="germany",PROPER('Raw data for Day5'!D155),IF('Raw data for Day5'!D155="usa",UPPER('Raw data for Day5'!D155),IF('Raw data for Day5'!D155="uk",UPPER('Raw data for Day5'!D155),IF('Raw data for Day5'!D155="india",PROPER('Raw data for Day5'!D155),'Raw data for Day5'!D155)))))) | F155: ='Raw data for Day5'!E155 -> 0 | G155: ='Raw data for Day5'!F155 -> 0 | H155: =CLEAN(TRIM('Raw data for Day5'!G155)) | I155: =CLEAN(TRIM('Raw data for Day5'!H155)) | J155: =CLEAN(TRIM(LOWER('Raw data for Day5'!I155)))
A156: =CLEAN(TRIM(LEFT('Raw data for Day5'!A156,3))) | B156: =CLEAN(TRIM(RIGHT('Raw data for Day5'!A156,4))) | C156: =CLEAN(TRIM(PROPER('Raw data for Day5'!B156))) | E156: =CLEAN(TRIM(IF('Raw data for Day5'!D156="germany",PROPER('Raw data for Day5'!D156),IF('Raw data for Day5'!D156="usa",UPPER('Raw data for Day5'!D156),IF('Raw data for Day5'!D156="uk",UPPER('Raw data for Day5'!D156),IF('Raw data for Day5'!D156="india",PROPER('Raw data for Day5'!D156),'Raw data for Day5'!D156)))))) | F156: ='Raw data for Day5'!E156 -> 0 | G156: ='Raw data for Day5'!F156 -> 0 | H156: =CLEAN(TRIM('Raw data for Day5'!G156)) | I156: =CLEAN(TRIM('Raw data for Day5'!H156)) | J156: =CLEAN(TRIM(LOWER('Raw data for Day5'!I156)))
